Workbook

Sheet Synthese-Electricite
A1: Période | B1: Solde_Import | C1: Imports | D1: Exports | E1: Conso_Brute | F1: Conso_CVC_CJO | G1: Conso_CVS | H1: DJU | I1: Indice_Rigueur | J1: Annee | K1: Mois | L1: Saison | M1: Période_chauffe | V1: DJU | W1: Conso_CVC_CJO
A2: 2022-12 | B2: 1890.73 | C2: 5629.246 | D2: 3738.515 | E2: 101402.13 | F2: 101739.33 | G2: 83658.932 | H2: 280.3 | I2: 0.976 | J2: =LEFT(A2,4)*1 -> 2022 | K2: =RIGHT(A2,2)*1 -> 12 | L2: =IF(OR(K2=12,K2<=2),"Hiver",IF(K2<=5,"Printemps",IF(K2<=8,"Été","Automne"))) -> Hiver | M2: =IF(AND(K2>=6,K2<=9),"Hors chauffe","Chauffe") -> Chauffe | V2: 280.3 | W2: 101739.33
A3: 2022-11 | B3: 1077.335 | C3: 4810.486 | D3: 3733.151 | E3: 80064.25 | F3: 82618.321 | G3: 79532.859 | H3: 144.9 | I3: 0.74 | J3: =LEFT(A3,4)*1 -> 2022 | K3: =RIGHT(A3,2)*1 -> 11 | L3: =IF(OR(K3=12,K3<=2),"Hiver",IF(K3<=5,"Printemps",IF(K3<=8,"Été","Automne"))) -> Automne | M3: =IF(AND(K3>=6,K3<=9),"Hors chauffe","Chauffe") -> Chauffe | V3: 144.9 | W3: 82618.321
A4: 2022-10 | B4: 275.665 | C4: 4114.793 | D4: 3839.128 | E4: 73237.539 | F4: 77235.451 | G4: 78871.996 | H4: 17.2 | I4: 0.232 | J4: =LEFT(A4,4)*1 -> 2022 | K4: =RIGHT(A4,2)*1 -> 10 | L4: =IF(OR(K4=12,K4<=2),"Hiver",IF(K4<=5,"Printemps",IF(K4<=8,"Été","Automne"))) -> Automne | M4: =IF(AND(K4>=6,K4<=9),"Hors chauffe","Chauffe") -> Chauffe | O4: TABLEAU DE CONTINGENCE PAR ANNEE | R4: TABLEAU DE CONTINGENCE PAR SAISON | V4: 17.2 | W4: 77235.451
A5: 2022-09 | B5: 3318.835 | C5: 5469.073 | D5: 2150.238 | E5: 68592.455 | F5: 68889.018 | G5: 79681.996 | H5: 0 | I5: 1 | J5: =LEFT(A5,4)*1 -> 2022 | K5: =RIGHT(A5,2)*1 -> 9 | L5: =IF(OR(K5=12,K5<=2),"Hiver",IF(K5<=5,"Printemps",IF(K5<=8,"Été","Automne"))) -> Automne | M5: =IF(AND(K5>=6,K5<=9),"Hors chauffe","Chauffe") -> Hors chauffe | V5: 0 | W5: 68889.018
A6: 2022-08 | B6: 3214.307 | C6: 5123.618 | D6: 1909.311 | E6: 68927.526 | F6: 67857.819 | G6: 80724.856 | H6: 0 | I6: 1 | J6: =LEFT(A6,4)*1 -> 2022 | K6: =RIGHT(A6,2)*1 -> 8 | L6: =IF(OR(K6=12,K6<=2),"Hiver",IF(K6<=5,"Printemps",IF(K6<=8,"Été","Automne"))) -> Été | M6: =IF(AND(K6>=6,K6<=9),"Hors chauffe","Chauffe") -> Hors chauffe | O6: Années | P6: Somme de Conso_CVC_CJO | R6: Saisons | S6: Moyenne de Conso_CVC_CJO | T6: Moyenne de DJU | V6: 0 | W6: 67857.819
A7: 2022-07 | B7: 3215.987 | C7: 5481.076 | D7: 2265.09 | E7: 71668.076 | F7: 71804.54 | G7: 82676.483 | H7: 0 | I7: 1 | J7: =LEFT(A7,4)*1 -> 2022 | K7: =RIGHT(A7,2)*1 -> 7 | L7: =IF(OR(K7=12,K7<=2),"Hiver",IF(K7<=5,"Printemps",IF(K7<=8,"Été","Automne"))) -> Été | M7: =IF(AND(K7>=6,K7<=9),"Hors chauffe","Chauffe") -> Hors chauffe | O7: 2006 | P7: 0 | R7: Automne | S7: 99766.046 | T7: 136.64828 | V7: 0 | W7: 71804.54
A8: 2022-06 | B8: 1063.461 | C8: 3813.163 | D8: 2749.701 | E8: 73782.824 | F8: 72673.889 | G8: 88025.517 | H8: 0 | I8: 1 | J8: =LEFT(A8,4)*1 -> 2022 | K8: =RIGHT(A8,2)*1 -> 6 | L8: =IF(OR(K8=12,K8<=2),"Hiver",IF(K8<=5,"Printemps",IF(K8<=8,"Été","Automne"))) -> Été | M8: =IF(AND(K8>=6,K8<=9),"Hors chauffe","Chauffe") -> Hors chauffe | O8: 2007 | P8: 0 | R8: Été | S8: 92233.004 | T8: #DIV/0! | V8: 0 | W8: 72673.889
A9: 2022-05 | B9: -620.846 | C9: 3083.756 | D9: 3704.602 | E9: 74686.534 | F9: 76347.869 | G9: 85006.433 | H9: 20.1 | I9: 0.429 | J9: =LEFT(A9,4)*1 -> 2022 | K9: =RIGHT(A9,2)*1 -> 5 | L9: =IF(OR(K9=12,K9<=2),"Hiver",IF(K9<=5,"Printemps",IF(K9<=8,"Été","Automne"))) -> Printemps | M9: =IF(AND(K9>=6,K9<=9),"Hors chauffe","Chauffe") -> Chauffe | O9: 2008 | P9: 0 | R9: Hiver | S9: 125834.14 | T9: 284.91087 | V9: 20.1 | W9: 76347.869
A10: 2022-04 | B10: 1086.988 | C10: 3789.507 | D10: 2702.519 | E10: 81459.791 | F10: 81476.797 | G10: 87440.564 | H10: 121 | I10: 1.031 | J10: =LEFT(A10,4)*1 -> 2022 | K10: =RIGHT(A10,2)*1 -> 4 | L10: =IF(OR(K10=12,K10<=2),"Hiver",IF(K10<=5,"Printemps",IF(K10<=8,"Été","Automne"))) -> Printemps | M10: =IF(AND(K10>=6,K10<=9),"Hors chauffe","Chauffe") -> Chauffe | O10: 2009 | P10: 0 | R10: Printemps | S10: 104259.86 | T10: 117.67609 | V10: 121 | W10: 81476.797
A11: 2022-03 | B11: 995.088 | C11: 4030.988 | D11: 3035.9 | E11: 96310.119 | F11: 98215.302 | G11: 90739.256 | H11: 173.3 | I11: 0.864 | J11: =LEFT(A11,4)*1 -> 2022 | K11: =RIGHT(A11,2)*1 -> 3 | L11: =IF(OR(K11=12,K11<=2),"Hiver",IF(K11<=5,"Printemps",IF(K11<=8,"Été","Automne"))) -> Printemps | M11: =IF(AND(K11>=6,K11<=9),"Hors chauffe","Chauffe") -> Chauffe | O11: 2010 | P11: 0 | R11: Total | S11: 105523.26 | T11: 185.8 | V11: 173.3 | W11: 98215.302
A12: 2022-02 | B12: -1844.439 | C12: 2325.285 | D12: 4169.724 | E12: 103088.95 | F12: 105420.47 | G12: 94179.117 | H12: 208.4 | I12: 0.808 | J12: =LEFT(A12,4)*1 -> 2022 | K12: =RIGHT(A12,2)*1 -> 2 | L12: =IF(OR(K12=12,K12<=2),"Hiver",IF(K12<=5,"Printemps",IF(K12<=8,"Été","Automne"))) -> Hiver | M12: =IF(AND(K12>=6,K12<=9),"Hors chauffe","Chauffe") -> Chauffe | O12: 2011 | P12: 1359615.6 | V12: 208.4 | W12: 105420.47
A13: 2022-01 | B13: 995.94 | C13: 4108.283 | D13: 3112.343 | E13: 122863.57 | F13: 122244.81 | G13: 94911.888 | H13: 321.8 | I13: 1.032 | J13: =LEFT(A13,4)*1 -> 2022 | K13: =RIGHT(A13,2)*1 -> 1 | L13: =IF(OR(K13=12,K13<=2),"Hiver",IF(K13<=5,"Printemps",IF(K13<=8,"Été","Automne"))) -> Hiver | M13: =IF(AND(K13>=6,K13<=9),"Hors chauffe","Chauffe") -> Chauffe | O13: 2012 | P13: 1322879.9 | V13: 321.8 | W13: 122244.81
A14: 2021-12 | B14: 1937.095 | C14: 4520.495 | D14: 2583.4 | E14: 112694.58 | F14: 113862.84 | G14: 95553.1 | H14: 260.3 | I14: 0.906 | J14: =LEFT(A14,4)*1 -> 2021 | K14: =RIGHT(A14,2)*1 -> 12 | L14: =IF(OR(K14=12,K14<=2),"Hiver",IF(K14<=5,"Printemps",IF(K14<=8,"Été","Automne"))) -> Hiver | M14: =IF(AND(K14>=6,K14<=9),"Hors chauffe","Chauffe") -> Chauffe | O14: 2013 | P14: 1320285.6 | V14: 260.3 | W14: 113862.84
A15: 2021-11 | B15: 799.768 | C15: 3621.99 | D15: 2822.222 | E15: 104963.78 | F15: 103338.45 | G15: 100818.7 | H15: 233.5 | I15: 1.192 | J15: =LEFT(A15,4)*1 -> 2021 | K15: =RIGHT(A15,2)*1 -> 11 | L15: =IF(OR(K15=12,K15<=2),"Hiver",IF(K15<=5,"Printemps",IF(K15<=8,"Été","Automne"))) -> Automne | M15: =IF(AND(K15>=6,K15<=9),"Hors chauffe","Chauffe") -> Chauffe | O15: 2014 | P15: 1358960.3 | V15: 233.5 | W15: 103338.45
A16: 2021-10 | B16: -4305.188 | C16: 1038.882 | D16: 5344.07 | E16: 101166.83 | F16: 100824.03 | G16: 102733.46 | H16: 81.3 | I16: 1.096 | J16: =LEFT(A16,4)*1 -> 2021 | K16: =RIGHT(A16,2)*1 -> 10 | L16: =IF(OR(K16=12,K16<=2),"Hiver",IF(K16<=5,"Printemps",IF(K16<=8,"Été","Automne"))) -> Automne | M16: =IF(AND(K16>=6,K16<=9),"Hors chauffe","Chauffe") -> Chauffe | O16: 2015 | P16: 1353111.3 | V16: 81.3 | W16: 100824.03
A17: 2021-09 | B17: -5788.223 | C17: 641.311 | D17: 6429.534 | E17: 93620.234 | F17: 93302.29 | G17: 104701.36 | H17: 0 | I17: 1 | J17: =LEFT(A17,4)*1 -> 2021 | K17: =RIGHT(A17,2)*1 -> 9 | L17: =IF(OR(K17=12,K17<=2),"Hiver",IF(K17<=5,"Printemps",IF(K17<=8,"Été","Automne"))) -> Automne | M17: =IF(AND(K17>=6,K17<=9),"Hors chauffe","Chauffe") -> Hors chauffe | O17: 2016 | P17: 1264433.2 | V17: 0 | W17: 93302.29
A18: 2021-08 | B18: -7641.946 | C18: 460.189 | D18: 8102.135 | E18: 93963.357 | F18: 94077.999 | G18: 107412.27 | H18: 0 | I18: 1 | J18: =LEFT(A18,4)*1 -> 2021 | K18: =RIGHT(A18,2)*1 -> 8 | L18: =IF(OR(K18=12,K18<=2),"Hiver",IF(K18<=5,"Printemps",IF(K18<=8,"Été","Automne"))) -> Été | M18: =IF(AND(K18>=6,K18<=9),"Hors chauffe","Chauffe") -> Hors chauffe | O18: 2017 | P18: 1254438.2 | V18: 0 | W18: 94077.999
A19: 2021-07 | B19: -7321.069 | C19: 741.902 | D19: 8062.97 | E19: 93634.792 | F19: 93748.603 | G19: 104938.93 | H19: 0 | I19: 1 | J19: =LEFT(A19,4)*1 -> 2021 | K19: =RIGHT(A19,2)*1 -> 7 | L19: =IF(OR(K19=12,K19<=2),"Hiver",IF(K19<=5,"Printemps",IF(K19<=8,"Été","Automne"))) -> Été | M19: =IF(AND(K19>=6,K19<=9),"Hors chauffe","Chauffe") -> Hors chauffe | O19: 2018 | P19: 1302240.1 | V19: 0 | W19: 93748.603
A20: 2021-06 | B20: -6851.46 | C20: 689.691 | D20: 7541.151 | E20: 90884.509 | F20: 89891.154 | G20: 105281.08 | H20: 0 | I20: 1 | J20: =LEFT(A20,4)*1 -> 2021 | K20: =RIGHT(A20,2)*1 -> 6 | L20: =IF(OR(K20=12,K20<=2),"Hiver",IF(K20<=5,"Printemps",IF(K20<=8,"Été","Automne"))) -> Été | M20: =IF(AND(K20>=6,K20<=9),"Hors chauffe","Chauffe") -> Hors chauffe | O20: 2019 | P20: 1262510.7 | V20: 0 | W20: 89891.154
A21: 2021-05 | B21: -5919.64 | C21: 1213.582 | D21: 7133.223 | E21: 94056.827 | F21: 91972.192 | G21: 100690.24 | H21: 79.2 | I21: 1.691 | J21: =LEFT(A21,4)*1 -> 2021 | K21: =RIGHT(A21,2)*1 -> 5 | L21: =IF(OR(K21=12,K21<=2),"Hiver",IF(K21<=5,"Printemps",IF(K21<=8,"Été","Automne"))) -> Printemps | M21: =IF(AND(K21>=6,K21<=9),"Hors chauffe","Chauffe") -> Chauffe | O21: 2020 | P21: 1154488.5 | V21: 79.2 | W21: 91972.192
A22: 2021-04 | B22: -1445.471 | C22: 2800.074 | D22: 4245.545 | E22: 93954.922 | F22: 92509.194 | G22: 98153.021 | H22: 167.2 | I22: 1.425 | J22: =LEFT(A22,4)*1 -> 2021 | K22: =RIGHT(A22,2)*1 -> 4 | L22: =IF(OR(K22=12,K22<=2),"Hiver",IF(K22<=5,"Printemps",IF(K22<=8,"Été","Automne"))) -> Printemps | M22: =IF(AND(K22>=6,K22<=9),"Hors chauffe","Chauffe") -> Chauffe | O22: 2021 | P22: 1215862.6 | V22: 167.2 | W22: 92509.194
A23: 2021-03 | B23: -3224.652 | C23: 2339.282 | D23: 5563.934 | E23: 108557.91 | F23: 108001.88 | G23: 99875.233 | H23: 209.3 | I23: 1.044 | J23: =LEFT(A23,4)*1 -> 2021 | K23: =RIGHT(A23,2)*1 -> 3 | L23: =IF(OR(K23=12,K23<=2),"Hiver",IF(K23<=5,"Printemps",IF(K23<=8,"Été","Automne"))) -> Printemps | M23: =IF(AND(K23>=6,K23<=9),"Hors chauffe","Chauffe") -> Chauffe | O23: 2022 | P23: 1026523.6 | V23: 209.3 | W23: 108001.88
A24: 2021-02 | B24: -3409.726 | C24: 2302.195 | D24: 5711.921 | E24: 105063.27 | F24: 107337.64 | G24: 95312.277 | H24: 210.2 | I24: 0.815 | J24: =LEFT(A24,4)*1 -> 2021 | K24: =RIGHT(A24,2)*1 -> 2 | L24: =IF(OR(K24=12,K24<=2),"Hiver",IF(K24<=5,"Printemps",IF(K24<=8,"Été","Automne"))) -> Hiver | M24: =IF(AND(K24>=6,K24<=9),"Hors chauffe","Chauffe") -> Chauffe | O24: Total | P24: 15195350 | V24: 210.2 | W24: 107337.64
A25: 2021-01 | B25: -1990.012 | C25: 3290.319 | D25: 5280.331 | E25: 128030.23 | F25: 126996.3 | G25: 99298.119 | H25: 331 | I25: 1.061 | J25: =LEFT(A25,4)*1 -> 2021 | K25: =RIGHT(A25,2)*1 -> 1 | L25: =IF(OR(K25=12,K25<=2),"Hiver",IF(K25<=5,"Printemps",IF(K25<=8,"Été","Automne"))) -> Hiver | M25: =IF(AND(K25>=6,K25<=9),"Hors chauffe","Chauffe") -> Chauffe | V25: 331 | W25: 126996.3
A26: 2020-12 | B26: -2444.321 | C26: 2523.323 | D26: 4967.644 | E26: 117708.07 | F26: 118633.63 | G26: 100883.41 | H26: 264.2 | I26: 0.92 | J26: =LEFT(A26,4)*1 -> 2020 | K26: =RIGHT(A26,2)*1 -> 12 | L26: =IF(OR(K26=12,K26<=2),"Hiver",IF(K26<=5,"Printemps",IF(K26<=8,"Été","Automne"))) -> Hiver | M26: =IF(AND(K26>=6,K26<=9),"Hors chauffe","Chauffe") -> Chauffe | V26: 264.2 | W26: 118633.63
A27: 2020-11 | B27: -4778.82 | C27: 1418.214 | D27: 6197.034 | E27: 104124.56 | F27: 106034.63 | G27: 104101.32 | H27: 153 | I27: 0.781 | J27: =LEFT(A27,4)*1 -> 2020 | K27: =RIGHT(A27,2)*1 -> 11 | L27: =IF(OR(K27=12,K27<=2),"Hiver",IF(K27<=5,"Printemps",IF(K27<=8,"Été","Automne"))) -> Automne | M27: =IF(AND(K27>=6,K27<=9),"Hors chauffe","Chauffe") -> Chauffe | O27: TABLEAU DE CONTINGENCE PAR MOIS | V27: 153 | W27: 106034.63
A28: 2020-10 | B28: -2838.676 | C28: 1858.294 | D28: 4696.97 | E28: 97778.277 | F28: 97153.659 | G28: 100752.51 | H28: 87.4 | I28: 1.178 | J28: =LEFT(A28,4)*1 -> 2020 | K28: =RIGHT(A28,2)*1 -> 10 | L28: =IF(OR(K28=12,K28<=2),"Hiver",IF(K28<=5,"Printemps",IF(K28<=8,"Été","Automne"))) -> Automne | M28: =IF(AND(K28>=6,K28<=9),"Hors chauffe","Chauffe") -> Chauffe | V28: 87.4 | W28: 97153.659
A29: 2020-09 | B29: 552.039 | C29: 3196.689 | D29: 2644.65 | E29: 77314.354 | F29: 77356.474 | G29: 89379.034 | H29: 0 | I29: 1 | J29: =LEFT(A29,4)*1 -> 2020 | K29: =RIGHT(A29,2)*1 -> 9 | L29: =IF(OR(K29=12,K29<=2),"Hiver",IF(K29<=5,"Printemps",IF(K29<=8,"Été","Automne"))) -> Automne | M29: =IF(AND(K29>=6,K29<=9),"Hors chauffe","Chauffe") -> Hors chauffe | O29: Mois | P29: Moyenne de Conso_CVC_CJO | V29: 0 | W29: 77356.474
A30: 2020-08 | B30: -1741.479 | C30: 2072.972 | D30: 3814.451 | E30: 79373.815 | F30: 78900.647 | G30: 91297.112 | H30: 0 | I30: 1 | J30: =LEFT(A30,4)*1 -> 2020 | K30: =RIGHT(A30,2)*1 -> 8 | L30: =IF(OR(K30=12,K30<=2),"Hiver",IF(K30<=5,"Printemps",IF(K30<=8,"Été","Automne"))) -> Été | M30: =IF(AND(K30>=6,K30<=9),"Hors chauffe","Chauffe") -> Hors chauffe | O30: Janvier | P30: 135177.57 | V30: 0 | W30: 78900.647
A31: 2020-07 | B31: -1300.921 | C31: 2287.017 | D31: 3587.938 | E31: 79613.834 | F31: 79794.891 | G31: 90564.532 | H31: 0 | I31: 1 | J31: =LEFT(A31,4)*1 -> 2020 | K31: =RIGHT(A31,2)*1 -> 7 | L31: =IF(OR(K31=12,K31<=2),"Hiver",IF(K31<=5,"Printemps",IF(K31<=8,"Été","Automne"))) -> Été | M31: =IF(AND(K31>=6,K31<=9),"Hors chauffe","Chauffe") -> Hors chauffe | O31: Février | P31: 118028.18 | V31: 0 | W31: 79794.891
A32: 2020-06 | B32: -3321.485 | C32: 1220.755 | D32: 4542.239 | E32: 75589.879 | F32: 75457.935 | G32: 90469.766 | H32: 0 | I32: 1 | J32: =LEFT(A32,4)*1 -> 2020 | K32: =RIGHT(A32,2)*1 -> 6 | L32: =IF(OR(K32=12,K32<=2),"Hiver",IF(K32<=5,"Printemps",IF(K32<=8,"Été","Automne"))) -> Été | M32: =IF(AND(K32>=6,K32<=9),"Hors chauffe","Chauffe") -> Hors chauffe | O32: Mars | P32: 115696.62 | V32: 0 | W32: 75457.935
A33: 2020-05 | B33: -6394.102 | C33: 555.781 | D33: 6949.883 | E33: 84323.429 | F33: 84761.683 | G33: 93020.742 | H33: 36.2 | I33: 0.773 | J33: =LEFT(A33,4)*1 -> 2020 | K33: =RIGHT(A33,2)*1 -> 5 | L33: =IF(OR(K33=12,K33<=2),"Hiver",IF(K33<=5,"Printemps",IF(K33<=8,"Été","Automne"))) -> Printemps | M33: =IF(AND(K33>=6,K33<=9),"Hors chauffe","Chauffe") -> Chauffe | O33: Avril | P33: 100687.92 | V33: 36.2 | W33: 84761.683
A34: 2020-04 | B34: -5693.375 | C34: 738.257 | D34: 6431.631 | E34: 89036.046 | F34: 91742.873 | G34: 96816.038 | H34: 58.6 | I34: 0.499 | J34: =LEFT(A34,4)*1 -> 2020 | K34: =RIGHT(A34,2)*1 -> 4 | L34: =IF(OR(K34=12,K34<=2),"Hiver",IF(K34<=5,"Printemps",IF(K34<=8,"Été","Automne"))) -> Printemps | M34: =IF(AND(K34>=6,K34<=9),"Hors chauffe","Chauffe") -> Chauffe | O34: Mai | P34: 96395.032 | V34: 58.6 | W34: 91742.873
A35: 2020-03 | B35: -5993.398 | C35: 978.975 | D35: 6972.373 | E35: 104830.06 | F35: 104942.89 | G35: 96106.156 | H35: 195 | I35: 0.972 | J35: =LEFT(A35,4)*1 -> 2020 | K35: =RIGHT(A35,2)*1 -> 3 | L35: =IF(OR(K35=12,K35<=2),"Hiver",IF(K35<=5,"Printemps",IF(K35<=8,"Été","Automne"))) -> Printemps | M35: =IF(AND(K35>=6,K35<=9),"Hors chauffe","Chauffe") -> Chauffe | O35: Juin | P35: 91147.257 | V35: 195 | W35: 104942.89
A36: 2020-02 | B36: -6751.129 | C36: 474.392 | D36: 7225.521 | E36: 112009.82 | F36: 112056.78 | G36: 100133.07 | H36: 181.1 | I36: 0.702 | J36: =LEFT(A36,4)*1 -> 2020 | K36: =RIGHT(A36,2)*1 -> 2 | L36: =IF(OR(K36=12,K36<=2),"Hiver",IF(K36<=5,"Printemps",IF(K36<=8,"Été","Automne"))) -> Hiver | M36: =IF(AND(K36>=6,K36<=9),"Hors chauffe","Chauffe") -> Chauffe | O36: Juillet | P36: 94815.572 | V36: 181.1 | W36: 112056.78
A37: 2020-01 | B37: -4517.428 | C37: 1516.862 | D37: 6034.29 | E37: 125409.8 | F37: 127652.38 | G37: 100260.79 | H37: 259.8 | I37: 0.833 | J37: =LEFT(A37,4)*1 -> 2020 | K37: =RIGHT(A37,2)*1 -> 1 | L37: =IF(OR(K37=12,K37<=2),"Hiver",IF(K37<=5,"Printemps",IF(K37<=8,"Été","Automne"))) -> Hiver | M37: =IF(AND(K37>=6,K37<=9),"Hors chauffe","Chauffe") -> Chauffe | O37: Août | P37: 90736.182 | V37: 259.8 | W37: 127652.38
A38: 2019-12 | B38: -3569.703 | C38: 2008.625 | D38: 5578.329 | E38: 115101.42 | F38: 116757.09 | G38: 98567.027 | H38: 235.4 | I38: 0.819 | J38: =LEFT(A38,4)*1 -> 2019 | K38: =RIGHT(A38,2)*1 -> 12 | L38: =IF(OR(K38=12,K38<=2),"Hiver",IF(K38<=5,"Printemps",IF(K38<=8,"Été","Automne"))) -> Hiver | M38: =IF(AND(K38>=6,K38<=9),"Hors chauffe","Chauffe") -> Chauffe | O38: Septembre | P38: 91593.673 | V38: 235.4 | W38: 116757.09
A39: 2019-11 | B39: -1388.136 | C39: 2814.769 | D39: 4202.904 | E39: 102333.25 | F39: 101727.06 | G39: 100062.81 | H39: 206.5 | I39: 1.055 | J39: =LEFT(A39,4)*1 -> 2019 | K39: =RIGHT(A39,2)*1 -> 11 | L39: =IF(OR(K39=12,K39<=2),"Hiver",IF(K39<=5,"Printemps",IF(K39<=8,"Été","Automne"))) -> Automne | M39: =IF(AND(K39>=6,K39<=9),"Hors chauffe","Chauffe") -> Chauffe | O39: Octobre | P39: 99910.3 | V39: 206.5 | W39: 101727.06
A40: 2019-10 | B40: -4282.494 | C40: 1292.912 | D40: 5575.405 | E40: 96851.237 | F40: 98557.437 | G40: 103108.01 | H40: 50.8 | I40: 0.685 | J40: =LEFT(A40,4)*1 -> 2019 | K40: =RIGHT(A40,2)*1 -> 10 | L40: =IF(OR(K40=12,K40<=2),"Hiver",IF(K40<=5,"Printemps",IF(K40<=8,"Été","Automne"))) -> Automne | M40: =IF(AND(K40>=6,K40<=9),"Hors chauffe","Chauffe") -> Chauffe | O40: Novembre | P40: 107794.16 | V40: 50.8 | W40: 98557.437
...

Sheet Stats
A1: STATS A UNE VARIABLE
A3: Indicateur | B3: Conso_CVC_CJO | C3: DJU | D3: Indice_Rigueur | E3: Solde_Import
A4: Moyenne | B4: =AVERAGE('Synthese-Electricite'!F:F) -> 105523.26 | C4: =AVERAGE('Synthese-Electricite'!H:H) -> 185.8 | D4: =AVERAGE('Synthese-Electricite'!I:I) -> 0.99777778 | E4: =AVERAGE('Synthese-Electricite'!B:B) -> -3861.4547
A5: Écart-type | B5: =_xlfn.STDEV.P('Synthese-Electricite'!F:F) -> 16392.508 | C5: =_xlfn.STDEV.P('Synthese-Electricite'!H:H) -> 102.05131 | D5: =_xlfn.STDEV.P('Synthese-Electricite'!I:I) -> 0.29305342 | E5: =_xlfn.STDEV.P('Synthese-Electricite'!B:B) -> 2394.4074
A6: Min | B6: =MIN('Synthese-Electricite'!F:F) -> 67857.819 | C6: =MIN('Synthese-Electricite'!H:H) -> 17.2 | D6: =MIN('Synthese-Electricite'!I:I) -> 0.232 | E6: =MIN('Synthese-Electricite'!B:B) -> -8166.72
A7: Max | B7: =MAX('Synthese-Electricite'!F:F) -> 142068.39 | C7: =MAX('Synthese-Electricite'!H:H) -> 415.5 | D7: =MAX('Synthese-Electricite'!I:I) -> 2.069 | E7: =MAX('Synthese-Electricite'!B:B) -> 3318.835
A8: Coef de variation | B8: =B5/B4 -> 0.15534497 | C8: =C5/C4 -> 0.54925357 | D8: =D5/D4 -> 0.2937061 | E8: =ABS(E5/E4) -> 0.62007911
A10: STATS A DEUX VARIABLES
A12: Coefficient de corrélation | B12: =CORREL('Synthese-Electricite'!F:F, 'Synthese-Electricite'!H:H) -> 0.76373052
A13: Coefficient de détermination (R²) | B13: =RSQ('Synthese-Electricite'!F:F, 'Synthese-Electricite'!H:H) -> 0.58328431
A14: Pente (a) | B14: =SLOPE('Synthese-Electricite'!F:F, 'Synthese-Electricite'!H:H) -> 117.98273
A15: Ordonnée à l'origine (b) | B15: =INTERCEPT('Synthese-Electricite'!F:F, 'Synthese-Electricite'!H:H) -> 91237.418
