Workbook

Sheet 4 1 Synthese-toutes-energies 20
A1: Période | B1: 1, Production totale | C1: 1,1 Production charbon | D1: 1,2 Production pétrole | E1: 1,3 Production gaz | F1: 1,4 Production nucléaire | G1: 1,5 Production ENR | H1: Production nucléaire + ENR | I1: 2,1 Imports total | J1: 2,2 Exports total | K1: 4, Conso totale | L1: 4,1 Conso charbon | M1: 4,2 Conso pétrole | N1: 4,3 Conso gaz | O1: Conso fossiles | P1: 4,4 Conso nucléaire + ENR | Q1: 5, Emissions CO2 | R1: 10, Taux d'indépendance | S1: Année | T1: Mois | U1: Part charbon | V1: Part pétrole | W1: Part Gaz | X1: Part Nucléaire ENR | Y1: Solde commercial | Z1: CO2 par GWh
A2: PERIODE | B2: PROD_ENER_SYNT | C2: PROD_CMS_SYNT | D2: PROD_PETRO_SYNT | E2: PROD_GAZ_SYNT | F2: PRODB_NUCL_SYNT | G2: PRODB_ELE_SYNT | I2: QIMP_ENER_SYNT | J2: QEXP_ENER_SYNT | K2: CP_ENER_SYNT | L2: CI_CMS_SYNT | M2: CONSO_PETRO_SYNT | N2: CONSO_GAZ_SYNT | P2: CONSO_ELE_SYNT | Q2: ECO2 | R2: TAUXIND_ENER_CUM
A3: 2022-12 | B3: 100729.47 | C3: 0 | D3: 574.574 | E3: 643.504 | F3: 89307.744 | G3: 10203.652 | H3: =SUM(F3,G3) -> 99511.396 | I3: 130729.59 | J3: 26816.959 | K3: 224335.89 | L3: 6656.956 | M3: 65321.358 | N3: 50955.448 | O3: =SUM(L3,M3,N3) -> 122933.76 | P3: 101402.13 | Q3: 28473.823 | R3: 44.884 | S3: =LEFT(A3,4)*1 -> 2022 | T3: =RIGHT(A3,2)*1 -> 12 | U3: =M3/K3 -> 0.29117658 | V3: =N3/K3 -> 0.22713908 | W3: =P3/K3 -> 0.45201028 | X3: =Q3/K3 -> 0.12692496 | Y3: =I3-J3 -> 103912.63 | Z3: =_4_1_Synthese_toutes_energies_2026_04[[#This Row],[5, Emissions CO2]]/_4_1_Synthese_toutes_energies_2026_04[[#This Row],[4, Conso totale]] -> 0.12692496
A4: 2022-11 | B4: 80137.477 | C4: 0 | D4: 550.345 | E4: 600.217 | F4: 69562.288 | G4: 9424.627 | H4: =SUM(F4,G4) -> 78986.915 | I4: 119824.84 | J4: 21738.483 | K4: 185934.12 | L4: 5209.02 | M4: 64279.274 | N4: 36381.573 | O4: =SUM(L4,M4,N4) -> 105869.87 | P4: 80064.25 | Q4: 24742.311 | R4: 44.924 | S4: =LEFT(A4,4)*1 -> 2022 | T4: =RIGHT(A4,2)*1 -> 11 | U4: =M4/K4 -> 0.34570995 | V4: =N4/K4 -> 0.19566916 | W4: =P4/K4 -> 0.43060548 | X4: =Q4/K4 -> 0.13307031 | Y4: =I4-J4 -> 98086.359 | Z4: =_4_1_Synthese_toutes_energies_2026_04[[#This Row],[5, Emissions CO2]]/_4_1_Synthese_toutes_energies_2026_04[[#This Row],[4, Conso totale]] -> 0.13307031
A5: 2022-10 | B5: 74126.177 | C5: 0 | D5: 557.195 | E5: 607.108 | F5: 65057.226 | G5: 7904.648 | H5: =SUM(F5,G5) -> 72961.874 | I5: 120497.7 | J5: 21895.122 | K5: 165831.72 | L5: 4562.098 | M5: 64631.362 | N5: 23400.723 | O5: =SUM(L5,M5,N5) -> 92594.183 | P5: 73237.539 | Q5: 21862.687 | R5: 45.116 | S5: =LEFT(A5,4)*1 -> 2022 | T5: =RIGHT(A5,2)*1 -> 10 | U5: =M5/K5 -> 0.38974064 | V5: =N5/K5 -> 0.14111126 | W5: =P5/K5 -> 0.44163769 | X5: =Q5/K5 -> 0.13183658 | Y5: =I5-J5 -> 98602.58 | Z5: =_4_1_Synthese_toutes_energies_2026_04[[#This Row],[5, Emissions CO2]]/_4_1_Synthese_toutes_energies_2026_04[[#This Row],[4, Conso totale]] -> 0.13183658
A6: 2022-09 | B6: 66361.959 | C6: 0 | D6: 523.092 | E6: 565.246 | F6: 58600.02 | G6: 6673.6 | H6: =SUM(F6,G6) -> 65273.62 | I6: 112550.97 | J6: 22588.886 | K6: 165414.26 | L6: 4621.048 | M6: 72503.498 | N6: 19697.257 | O6: =SUM(L6,M6,N6) -> 96821.803 | P6: 68592.455 | Q6: 22735.099 | R6: 45.558 | S6: =LEFT(A6,4)*1 -> 2022 | T6: =RIGHT(A6,2)*1 -> 9 | U6: =M6/K6 -> 0.43831468 | V6: =N6/K6 -> 0.11907835 | W6: =P6/K6 -> 0.41467075 | X6: =Q6/K6 -> 0.13744341 | Y6: =I6-J6 -> 89962.08 | Z6: =_4_1_Synthese_toutes_energies_2026_04[[#This Row],[5, Emissions CO2]]/_4_1_Synthese_toutes_energies_2026_04[[#This Row],[4, Conso totale]] -> 0.13744341
A7: 2022-08 | B7: 66789.792 | C7: 0 | D7: 532.486 | E7: 544.087 | F7: 58554.054 | G7: 7159.165 | H7: =SUM(F7,G7) -> 65713.219 | I7: 122051.08 | J7: 23696.691 | K7: 158116.21 | L7: 5188.196 | M7: 68438.407 | N7: 15562.08 | O7: =SUM(L7,M7,N7) -> 89188.683 | P7: 68927.526 | Q7: 20885.91 | R7: 46.485 | S7: =LEFT(A7,4)*1 -> 2022 | T7: =RIGHT(A7,2)*1 -> 8 | U7: =M7/K7 -> 0.43283612 | V7: =N7/K7 -> 0.098421787 | W7: =P7/K7 -> 0.43592954 | X7: =Q7/K7 -> 0.13209215 | Y7: =I7-J7 -> 98354.386 | Z7: =_4_1_Synthese_toutes_energies_2026_04[[#This Row],[5, Emissions CO2]]/_4_1_Synthese_toutes_energies_2026_04[[#This Row],[4, Conso totale]] -> 0.13209215
A8: 2022-07 | B8: 69544.398 | C8: 0 | D8: 560.082 | E8: 532.227 | F8: 60385.593 | G8: 8066.496 | H8: =SUM(F8,G8) -> 68452.089 | I8: 134363.02 | J8: 22052.259 | K8: 163971.59 | L8: 4928.938 | M8: 70255.579 | N8: 17118.995 | O8: =SUM(L8,M8,N8) -> 92303.512 | P8: 71668.076 | Q8: 20873.255 | R8: 47.468 | S8: =LEFT(A8,4)*1 -> 2022 | T8: =RIGHT(A8,2)*1 -> 7 | U8: =M8/K8 -> 0.42846191 | V8: =N8/K8 -> 0.1044022 | W8: =P8/K8 -> 0.43707618 | X8: =Q8/K8 -> 0.127298 | Y8: =I8-J8 -> 112310.76 | Z8: =_4_1_Synthese_toutes_energies_2026_04[[#This Row],[5, Emissions CO2]]/_4_1_Synthese_toutes_energies_2026_04[[#This Row],[4, Conso totale]] -> 0.127298
A9: 2022-06 | B9: 73797.804 | C9: 0 | D9: 589.512 | E9: 488.93 | F9: 64482.038 | G9: 8237.324 | H9: =SUM(F9,G9) -> 72719.362 | I9: 112713.85 | J9: 19913.378 | K9: 163881.63 | L9: 5162.255 | M9: 67846.447 | N9: 17090.107 | O9: =SUM(L9,M9,N9) -> 90098.809 | P9: 73782.824 | Q9: 20464.408 | R9: 48.308 | S9: =LEFT(A9,4)*1 -> 2022 | T9: =RIGHT(A9,2)*1 -> 6 | U9: =M9/K9 -> 0.41399665 | V9: =N9/K9 -> 0.10428324 | W9: =P9/K9 -> 0.45022021 | X9: =Q9/K9 -> 0.1248731 | Y9: =I9-J9 -> 92800.472 | Z9: =_4_1_Synthese_toutes_energies_2026_04[[#This Row],[5, Emissions CO2]]/_4_1_Synthese_toutes_energies_2026_04[[#This Row],[4, Conso totale]] -> 0.1248731
A10: 2022-05 | B10: 76443.366 | C10: 0 | D10: 612.834 | E10: 523.152 | F10: 65809.978 | G10: 9497.402 | H10: =SUM(F10,G10) -> 75307.38 | I10: 131307.2 | J10: 23566.461 | K10: 165071.62 | L10: 5304.965 | M10: 64846.254 | N10: 20233.866 | O10: =SUM(L10,M10,N10) -> 90385.085 | P10: 74686.534 | Q10: 21017.409 | R10: 48.945 | S10: =LEFT(A10,4)*1 -> 2022 | T10: =RIGHT(A10,2)*1 -> 5 | U10: =M10/K10 -> 0.39283709 | V10: =N10/K10 -> 0.12257629 | W10: =P10/K10 -> 0.45244928 | X10: =Q10/K10 -> 0.12732297 | Y10: =I10-J10 -> 107740.74 | Z10: =_4_1_Synthese_toutes_energies_2026_04[[#This Row],[5, Emissions CO2]]/_4_1_Synthese_toutes_energies_2026_04[[#This Row],[4, Conso totale]] -> 0.12732297
A11: 2022-04 | B11: 81487.623 | C11: 0 | D11: 602.05 | E11: 512.769 | F11: 69785.579 | G11: 10587.225 | H11: =SUM(F11,G11) -> 80372.804 | I11: 125456.02 | J11: 21245.204 | K11: 180066.35 | L11: 4739.976 | M11: 61794.634 | N11: 32071.951 | O11: =SUM(L11,M11,N11) -> 98606.561 | P11: 81459.791 | Q11: 22794.817 | R11: 49.515 | S11: =LEFT(A11,4)*1 -> 2022 | T11: =RIGHT(A11,2)*1 -> 4 | U11: =M11/K11 -> 0.34317702 | V11: =N11/K11 -> 0.17811185 | W11: =P11/K11 -> 0.45238764 | X11: =Q11/K11 -> 0.12659121 | Y11: =I11-J11 -> 104210.81 | Z11: =_4_1_Synthese_toutes_energies_2026_04[[#This Row],[5, Emissions CO2]]/_4_1_Synthese_toutes_energies_2026_04[[#This Row],[4, Conso totale]] -> 0.12659121
A12: 2022-03 | B12: 96469.528 | C12: 0 | D12: 634.333 | E12: 520.164 | F12: 85750.867 | G12: 9564.164 | H12: =SUM(F12,G12) -> 95315.031 | I12: 135224.77 | J12: 19794.914 | K12: 214743.66 | L12: 6943.072 | M12: 69098.022 | N12: 42392.451 | O12: =SUM(L12,M12,N12) -> 118433.54 | P12: 96310.119 | Q12: 27182.589 | R12: 49.813 | S12: =LEFT(A12,4)*1 -> 2022 | T12: =RIGHT(A12,2)*1 -> 3 | U12: =M12/K12 -> 0.32176978 | V12: =N12/K12 -> 0.19740955 | W12: =P12/K12 -> 0.44848876 | X12: =Q12/K12 -> 0.12658156 | Y12: =I12-J12 -> 115429.86 | Z12: =_4_1_Synthese_toutes_energies_2026_04[[#This Row],[5, Emissions CO2]]/_4_1_Synthese_toutes_energies_2026_04[[#This Row],[4, Conso totale]] -> 0.12658156
A13: 2022-02 | B13: 105939.72 | C13: 0 | D13: 563.59 | E13: 442.74 | F13: 94127.124 | G13: 10806.264 | H13: =SUM(F13,G13) -> 104933.39 | I13: 107770.38 | J13: 19155.971 | K13: 218307.5 | L13: 6817.331 | M13: 63052.823 | N13: 45348.396 | O13: =SUM(L13,M13,N13) -> 115218.55 | P13: 103088.95 | Q13: 26121.538 | R13: 50.148 | S13: =LEFT(A13,4)*1 -> 2022 | T13: =RIGHT(A13,2)*1 -> 2 | U13: =M13/K13 -> 0.28882573 | V13: =N13/K13 -> 0.20772716 | W13: =P13/K13 -> 0.472219 | X13: =Q13/K13 -> 0.11965479 | Y13: =I13-J13 -> 88614.408 | Z13: =_4_1_Synthese_toutes_energies_2026_04[[#This Row],[5, Emissions CO2]]/_4_1_Synthese_toutes_energies_2026_04[[#This Row],[4, Conso totale]] -> 0.11965479
A14: 2022-01 | B14: 122963.49 | C14: 0 | D14: 623.661 | E14: 472.199 | F14: 111862.4 | G14: 10005.228 | H14: =SUM(F14,G14) -> 121867.63 | I14: 128714.9 | J14: 22249.814 | K14: 255223.16 | L14: 7333.346 | M14: 63972.507 | N14: 61053.741 | O14: =SUM(L14,M14,N14) -> 132359.59 | P14: 122863.57 | Q14: 29528.624 | R14: 50.255 | S14: =LEFT(A14,4)*1 -> 2022 | T14: =RIGHT(A14,2)*1 -> 1 | U14: =M14/K14 -> 0.25065322 | V14: =N14/K14 -> 0.23921708 | W14: =P14/K14 -> 0.48139662 | X14: =Q14/K14 -> 0.11569727 | Y14: =I14-J14 -> 106465.09 | Z14: =_4_1_Synthese_toutes_energies_2026_04[[#This Row],[5, Emissions CO2]]/_4_1_Synthese_toutes_energies_2026_04[[#This Row],[4, Conso totale]] -> 0.11569727
... A28: 2020-11 | B28: 109782.9 | C28: 0 | D28: 646.973 | E28: 232.553 | F28: 100429.25 | G28: 8474.122 | H28: =SUM(F28,G28) -> 108903.38 | I28: 109894.63 | J28: 22458.284 | K28: 207991.03 | L28: 5715.486 | M28: 54313.169 | N28: 43837.822 | O28: =SUM(L28,M28,N28) -> 103866.48 | P28: 104124.56 | Q28: 22663.078 | R28: 51.088 | S28: =LEFT(A28,4)*1 -> 2020 | T28: =RIGHT(A28,2)*1 -> 11 | U28: =M28/K28 -> 0.26113226 | V28: =N28/K28 -> 0.21076785 | W28: =P28/K28 -> 0.50062041 | X28: =Q28/K28 -> 0.1089618 | Y28: =I28-J28 -> 87436.348 | Z28: =_4_1_Synthese_toutes_energies_2026_04[[#This Row],[5, Emissions CO2]]/_4_1_Synthese_toutes_energies_2026_04[[#This Row],[4, Conso totale]] -> 0.1089618
A29: 2020-10 | B29: 101525.17 | C29: 0 | D29: 694.017 | E29: 214.199 | F29: 90211.446 | G29: 10405.507 | H29: =SUM(F29,G29) -> 100616.95 | I29: 116933.2 | J29: 18449.421 | K29: 206368.33 | L29: 5286 | M29: 68990.522 | N29: 34313.529 | O29: =SUM(L29,M29,N29) -> 103304.05 | P29: 97778.277 | Q29: 24319.416 | R29: 50.396 | S29: =LEFT(A29,4)*1 -> 2020 | T29: =RIGHT(A29,2)*1 -> 10 | U29: =M29/K29 -> 0.33430771 | V29: =N29/K29 -> 0.16627323 | W29: =P29/K29 -> 0.47380467 | X29: =Q29/K29 -> 0.11784471 | Y29: =I29-J29 -> 98483.777 | Z29: =_4_1_Synthese_toutes_energies_2026_04[[#This Row],[5, Emissions CO2]]/_4_1_Synthese_toutes_energies_2026_04[[#This Row],[4, Conso totale]] -> 0.11784471
A30: 2020-09 | B30: 77602.294 | C30: 0 | D30: 670.598 | E30: 169.381 | F30: 69877.497 | G30: 6884.818 | H30: =SUM(F30,G30) -> 76762.315 | I30: 107135.69 | J30: 19728.94 | K30: 171334.58 | L30: 5521.937 | M30: 67821.017 | N30: 20677.267 | O30: =SUM(L30,M30,N30) -> 94020.221 | P30: 77314.354 | Q30: 21216.001 | R30: 50.331 | S30: =LEFT(A30,4)*1 -> 2020 | T30: =RIGHT(A30,2)*1 -> 9 | U30: =M30/K30 -> 0.39583964 | V30: =N30/K30 -> 0.12068356 | W30: =P30/K30 -> 0.45124782 | X30: =Q30/K30 -> 0.1238279 | Y30: =I30-J30 -> 87406.748 | Z30: =_4_1_Synthese_toutes_energies_2026_04[[#This Row],[5, Emissions CO2]]/_4_1_Synthese_toutes_energies_2026_04[[#This Row],[4, Conso totale]] -> 0.1238279
A31: 2020-08 | B31: 81972.313 | C31: 0 | D31: 686.454 | E31: 170.565 | F31: 73715.969 | G31: 7399.325 | H31: =SUM(F31,G31) -> 81115.294 | I31: 109287.55 | J31: 20941.084 | K31: 162187.94 | L31: 4574.662 | M31: 61741.956 | N31: 16497.512 | O31: =SUM(L31,M31,N31) -> 82814.13 | P31: 79373.815 | Q31: 18754.808 | R31: 50.632 | S31: =LEFT(A31,4)*1 -> 2020 | T31: =RIGHT(A31,2)*1 -> 8 | U31: =M31/K31 -> 0.38068154 | V31: =N31/K31 -> 0.10171849 | W31: =P31/K31 -> 0.48939405 | X31: =Q31/K31 -> 0.11563626 | Y31: =I31-J31 -> 88346.468 | Z31: =_4_1_Synthese_toutes_energies_2026_04[[#This Row],[5, Emissions CO2]]/_4_1_Synthese_toutes_energies_2026_04[[#This Row],[4, Conso totale]] -> 0.11563626
A32: 2020-07 | B32: 81744.634 | C32: 0 | D32: 659.146 | E32: 170.733 | F32: 72325.808 | G32: 8588.947 | H32: =SUM(F32,G32) -> 80914.755 | I32: 109687.44 | J32: 23761.375 | K32: 172399.23 | L32: 4697.799 | M32: 69557.301 | N32: 18530.295 | O32: =SUM(L32,M32,N32) -> 92785.395 | P32: 79613.834 | Q32: 20644.256 | R32: 50.764 | S32: =LEFT(A32,4)*1 -> 2020 | T32: =RIGHT(A32,2)*1 -> 7 | U32: =M32/K32 -> 0.40346643 | V32: =N32/K32 -> 0.10748479 | W32: =P32/K32 -> 0.46179925 | X32: =Q32/K32 -> 0.1197468 | Y32: =I32-J32 -> 85926.061 | Z32: =_4_1_Synthese_toutes_energies_2026_04[[#This Row],[5, Emissions CO2]]/_4_1_Synthese_toutes_energies_2026_04[[#This Row],[4, Conso totale]] -> 0.1197468
A33: 2020-06 | B33: 79671.085 | C33: 0 | D33: 597.658 | E33: 162.063 | F33: 68777.753 | G33: 10133.611 | H33: =SUM(F33,G33) -> 78911.364 | I33: 109907.02 | J33: 21176.344 | K33: 158949.21 | L33: 3649.544 | M33: 60431.926 | N33: 19277.864 | O33: =SUM(L33,M33,N33) -> 83359.334 | P33: 75589.879 | Q33: 18535.758 | R33: 50.958 | S33: =LEFT(A33,4)*1 -> 2020 | T33: =RIGHT(A33,2)*1 -> 6 | U33: =M33/K33 -> 0.38019644 | V33: =N33/K33 -> 0.12128317 | W33: =P33/K33 -> 0.47555994 | X33: =Q33/K33 -> 0.11661434 | Y33: =I33-J33 -> 88730.678 | Z33: =_4_1_Synthese_toutes_energies_2026_04[[#This Row],[5, Emissions CO2]]/_4_1_Synthese_toutes_energies_2026_04[[#This Row],[4, Conso totale]] -> 0.11661434
A34: 2020-05 | B34: 91285.305 | C34: 0 | D34: 401.085 | E34: 166.689 | F34: 79563.073 | G34: 11154.458 | H34: =SUM(F34,G34) -> 90717.531 | I34: 119653.35 | J34: 21358.336 | K34: 159352.36 | L34: 4394.053 | M34: 50712.505 | N34: 19922.374 | O34: =SUM(L34,M34,N34) -> 75028.932 | P34: 84323.429 | Q34: 16738.677 | R34: 51.165 | S34: =LEFT(A34,4)*1 -> 2020 | T34: =RIGHT(A34,2)*1 -> 5 | U34: =M34/K34 -> 0.31824132 | V34: =N34/K34 -> 0.12502089 | W34: =P34/K34 -> 0.52916335 | X34: =Q34/K34 -> 0.10504191 | Y34: =I34-J34 -> 98295.011 | Z34: =_4_1_Synthese_toutes_energies_2026_04[[#This Row],[5, Emissions CO2]]/_4_1_Synthese_toutes_energies_2026_04[[#This Row],[4, Conso totale]] -> 0.10504191
A35: 2020-04 | B35: 95343.117 | C35: 0 | D35: 452.636 | E35: 161.06 | F35: 85870.559 | G35: 8858.861 | H35: =SUM(F35,G35) -> 94729.42 | I35: 104086.1 | J35: 24033.743 | K35: 156717.95 | L35: 4122.118 | M35: 42171.218 | N35: 21388.563 | O35: =SUM(L35,M35,N35) -> 67681.899 | P35: 89036.046 | Q35: 14804.465 | R35: 50.948 | S35: =LEFT(A35,4)*1 -> 2020 | T35: =RIGHT(A35,2)*1 -> 4 | U35: =M35/K35 -> 0.26908991 | V35: =N35/K35 -> 0.13647807 | W35: =P35/K35 -> 0.56812923 | X35: =Q35/K35 -> 0.094465666 | Y35: =I35-J35 -> 80052.36 | Z35: =_4_1_Synthese_toutes_energies_2026_04[[#This Row],[5, Emissions CO2]]/_4_1_Synthese_toutes_energies_2026_04[[#This Row],[4, Conso totale]] -> 0.094465666
A36: 2020-03 | B36: 111681.28 | C36: 0 | D36: 695.812 | E36: 162.004 | F36: 97714.37 | G36: 13109.09 | H36: =SUM(F36,G36) -> 110823.46 | I36: 122199.76 | J36: 25216.644 | K36: 215638.79 | L36: 5403.932 | M36: 61447.276 | N36: 43957.515 | O36: =SUM(L36,M36,N36) -> 110808.72 | P36: 104830.06 | Q36: 24593.408 | R36: 50.318 | S36: =LEFT(A36,4)*1 -> 2020 | T36: =RIGHT(A36,2)*1 -> 3 | U36: =M36/K36 -> 0.28495466 | V36: =N36/K36 -> 0.20384791 | W36: =P36/K36 -> 0.48613732 | X36: =Q36/K36 -> 0.11404909 | Y36: =I36-J36 -> 96983.117 | Z36: =_4_1_Synthese_toutes_energies_2026_04[[#This Row],[5, Emissions CO2]]/_4_1_Synthese_toutes_energies_2026_04[[#This Row],[4, Conso totale]] -> 0.11404909
A37: 2020-02 | B37: 119587.17 | C37: 0 | D37: 684.779 | E37: 141.437 | F37: 105638.33 | G37: 13122.62 | H37: =SUM(F37,G37) -> 118760.95 | I37: 111452.61 | J37: 26185.582 | K37: 232012.86 | L37: 6175.219 | M37: 67059.143 | N37: 46768.672 | O37: =SUM(L37,M37,N37) -> 120003.03 | P37: 112009.82 | Q37: 27227.207 | R37: 50.393 | S37: =LEFT(A37,4)*1 -> 2020 | T37: =RIGHT(A37,2)*1 -> 2 | U37: =M37/K37 -> 0.28903201 | V37: =N37/K37 -> 0.20157793 | W37: =P37/K37 -> 0.48277421 | X37: =Q37/K37 -> 0.11735215 | Y37: =I37-J37 -> 85267.026 | Z37: =_4_1_Synthese_toutes_energies_2026_04[[#This Row],[5, Emissions CO2]]/_4_1_Synthese_toutes_energies_2026_04[[#This Row],[4, Conso totale]] -> 0.11735215
A38: 2020-01 | B38: 130780.03 | C38: 0 | D38: 708.491 | E38: 144.302 | F38: 118755.94 | G38: 11171.291 | H38: =SUM(F38,G38) -> 129927.23 | I38: 117276.77 | J38: 24221.929 | K38: 262024.67 | L38: 6829.447 | M38: 71479.834 | N38: 58305.58 | O38: =SUM(L38,M38,N38) -> 136614.86 | P38: 125409.8 | Q38: 30979.055 | R38: 50.381 | S38: =LEFT(A38,4)*1 -> 2020 | T38: =RIGHT(A38,2)*1 -> 1 | U38: =M38/K38 -> 0.27279811 | V38: =N38/K38 -> 0.22251943 | W38: =P38/K38 -> 0.47861832 | X38: =Q38/K38 -> 0.11822954 | Y38: =I38-J38 -> 93054.841 | Z38: =_4_1_Synthese_toutes_energies_2026_04[[#This Row],[5, Emissions CO2]]/_4_1_Synthese_toutes_energies_2026_04[[#This Row],[4, Conso totale]] -> 0.11822954
A39: 2019-12 | B39: 119523.96 | C39: 0 | D39: 711.07 | E39: 141.767 | F39: 105413.8 | G39: 13257.324 | H39: =SUM(F39,G39) -> 118671.12 | I39: 127542.97 | J39: 23163.775 | K39: 244893.79 | L39: 6347.978 | M39: 69780.583 | N39: 53663.806 | O39: =SUM(L39,M39,N39) -> 129792.37 | P39: 115101.42 | Q39: 29575.141 | R39: 50.214 | S39: =LEFT(A39,4)*1 -> 2019 | T39: =RIGHT(A39,2)*1 -> 12 | U39: =M39/K39 -> 0.28494223 | V39: =N39/K39 -> 0.21913094 | W39: =P39/K39 -> 0.47000548 | X39: =Q39/K39 -> 0.12076722 | Y39: =I39-J39 -> 104379.19 | Z39: =_4_1_Synthese_toutes_energies_2026_04[[#This Row],[5, Emissions CO2]]/_4_1_Synthese_toutes_energies_2026_04[[#This Row],[4, Conso totale]] -> 0.12076722
A40: 2019-11 | B40: 104563.24 | C40: 0 | D40: 717.652 | E40: 124.2 | F40: 93100.702 | G40: 10620.685 | H40: =SUM(F40,G40) -> 103721.39 | I40: 137799.98 | J40: 22131.825 | K40: 229887.71 | L40: 6786.145 | M40: 70062.367 | N40: 50705.944 | O40: =SUM(L40,M40,N40) -> 127554.46 | P40: 102333.25 | Q40: 28744.404 | R40: 50.498 | S40: =LEFT(A40,4)*1 -> 2019 | T40: =RIGHT(A40,2)*1 -> 11 | U40: =M40/K40 -> 0.30476778 | V40: =N40/K40 -> 0.22056831 | W40: =P40/K40 -> 0.44514451 | X40: =Q40/K40 -> 0.12503672 | Y40: =I40-J40 -> 115668.15 | Z40: =_4_1_Synthese_toutes_energies_2026_04[[#This Row],[5, Emissions CO2]]/_4_1_Synthese_toutes_energies_2026_04[[#This Row],[4, Conso totale]] -> 0.12503672
A41: 2019-10 | B41: 102025.17 | C41: 0 | D41: 768.743 | E41: 122.7 | F41: 92959.701 | G41: 8174.03 | H41: =SUM(F41,G41) -> 101133.73 | I41: 136373.68 | J41: 26100.488 | K41: 210440.2 | L41: 5924.778 | M41: 77481.474 | N41: 30182.709 | O41: =SUM(L41,M41,N41) -> 113588.96 | P41: 96851.237 | Q41: 25740.879 | R41: 50.636 | S41: =LEFT(A41,4)*1 -> 2019 | T41: =RIGHT(A41,2)*1 -> 10 | U41: =M41/K41 -> 0.36818761 | V41: =N41/K41 -> 0.14342654 | W41: =P41/K41 -> 0.46023164 | X41: =Q41/K41 -> 0.12231921 | Y41: =I41-J41 -> 110273.19 | Z41: =_4_1_Synthese_toutes_energies_2026_04[[#This Row],[5, Emissions CO2]]/_4_1_Synthese_toutes_energies_2026_04[[#This Row],[4, Conso totale]] -> 0.12231921
... A49: 2019-02 | B49: 123646.93 | C49: 0 | D49: 694.311 | E49: 89.601 | F49: 114250.76 | G49: 8612.26 | H49: =SUM(F49,G49) -> 122863.02 | I49: 128583.09 | J49: 32616.191 | K49: 240705.85 | L49: 6606.937 | M49: 66723.876 | N49: 50038.158 | O49: =SUM(L49,M49,N49) -> 123368.97 | P49: 117336.87 | Q49: 27900.272 | R49: 50.648 | S49: =LEFT(A49,4)*1 -> 2019 | T49: =RIGHT(A49,2)*1 -> 2 | U49: =M49/K49 -> 0.2772009 | V49: =N49/K49 -> 0.20788094 | W49: =P49/K49 -> 0.48746998 | X49: =Q49/K49 -> 0.11591024 | Y49: =I49-J49 -> 95966.894 | Z49: =_4_1_Synthese_toutes_energies_2026_04[[#This Row],[5, Emissions CO2]]/_4_1_Synthese_toutes_energies_2026_04[[#This Row],[4, Conso totale]] -> 0.11591024
A50: 2019-01 | B50: 136813 | C50: 0 | D50: 751.659 | E50: 85.931 | F50: 127358.57 | G50: 8616.836 | H50: =SUM(F50,G50) -> 135975.41 | I50: 144477.93 | J50: 25706.576 | K50: 282755.01 | L50: 7552.786 | M50: 74074.462 | N50: 66486.402 | O50: =SUM(L50,M50,N50) -> 148113.65 | P50: 134641.36 | Q50: 33176.821 | R50: 50.31 | S50: =LEFT(A50,4)*1 -> 2019 | T50: =RIGHT(A50,2)*1 -> 1 | U50: =M50/K50 -> 0.261974 | V50: =N50/K50 -> 0.23513784 | W50: =P50/K50 -> 0.47617675 | X50: =Q50/K50 -> 0.11733416 | Y50: =I50-J50 -> 118771.35 | Z50: =_4_1_Synthese_toutes_energies_2026_04[[#This Row],[5, Emissions CO2]]/_4_1_Synthese_toutes_energies_2026_04[[#This Row],[4, Conso totale]] -> 0.11733416
A51: 2018-12 | B51: 133532.97 | C51: 0 | D51: 750.275 | E51: 81.529 | F51: 123406.02 | G51: 9295.144 | H51: =SUM(F51,G51) -> 132701.16 | I51: 139983.27 | J51: 32603.913 | K51: 257777.16 | L51: 7406.162 | M51: 68595.722 | N51: 54317.722 | O51: =SUM(L51,M51,N51) -> 130319.61 | P51: 127457.56 | Q51: 29819.382 | R51: 50.843 | S51: =LEFT(A51,4)*1 -> 2018 | T51: =RIGHT(A51,2)*1 -> 12 | U51: =M51/K51 -> 0.26610473 | V51: =N51/K51 -> 0.2107158 | W51: =P51/K51 -> 0.4944486 | X51: =Q51/K51 -> 0.11567891 | Y51: =I51-J51 -> 107379.36 | Z51: =_4_1_Synthese_toutes_energies_2026_04[[#This Row],[5, Emissions CO2]]/_4_1_Synthese_toutes_energies_2026_04[[#This Row],[4, Conso totale]] -> 0.11567891
A52: 2018-11 | B52: 112157.78 | C52: 0 | D52: 733.574 | E52: 67.587 | F52: 103937.52 | G52: 7419.094 | H52: =SUM(F52,G52) -> 111356.61 | I52: 135628.04 | J52: 21909.576 | K52: 237663.45 | L52: 8211.779 | M52: 70143.262 | N52: 49876.313 | O52: =SUM(L52,M52,N52) -> 128231.35 | P52: 109432.1 | Q52: 29588.454 | R52: 50.441 | S52: =LEFT(A52,4)*1 -> 2018 | T52: =RIGHT(A52,2)*1 -> 11 | U52: =M52/K52 -> 0.29513693 | V52: =N52/K52 -> 0.2098611 | W52: =P52/K52 -> 0.46044984 | X52: =Q52/K52 -> 0.12449728 | Y52: =I52-J52 -> 113718.47 | Z52: =_4_1_Synthese_toutes_energies_2026_04[[#This Row],[5, Emissions CO2]]/_4_1_Synthese_toutes_energies_2026_04[[#This Row],[4, Conso totale]] -> 0.12449728
A53: 2018-10 | B53: 107960.62 | C53: 0 | D53: 779.617 | E53: 74.697 | F53: 100772.21 | G53: 6334.095 | H53: =SUM(F53,G53) -> 107106.31 | I53: 149563.01 | J53: 28004.977 | K53: 223244.96 | L53: 8514.343 | M53: 80731.743 | N53: 31473.722 | O53: =SUM(L53,M53,N53) -> 120719.81 | P53: 102525.15 | Q53: 28257.318 | R53: 50.196 | S53: =LEFT(A53,4)*1 -> 2018 | T53: =RIGHT(A53,2)*1 -> 10 | U53: =M53/K53 -> 0.36162851 | V53: =N53/K53 -> 0.1409829 | W53: =P53/K53 -> 0.45924957 | X53: =Q53/K53 -> 0.12657539 | Y53: =I53-J53 -> 121558.04 | Z53: =_4_1_Synthese_toutes_energies_2026_04[[#This Row],[5, Emissions CO2]]/_4_1_Synthese_toutes_energies_2026_04[[#This Row],[4, Conso totale]] -> 0.12657539
A54: 2018-09 | B54: 102848.96 | C54: 0 | D54: 742.006 | E54: 65.033 | F54: 96104.598 | G54: 5937.32 | H54: =SUM(F54,G54) -> 102041.92 | I54: 132703.77 | J54: 26016.761 | K54: 195630.79 | L54: 7498.479 | M54: 72292.19 | N54: 19403.286 | O54: =SUM(L54,M54,N54) -> 99193.955 | P54: 96436.834 | Q54: 22887.281 | R54: 50.07 | S54: =LEFT(A54,4)*1 -> 2018 | T54: =RIGHT(A54,2)*1 -> 9 | U54: =M54/K54 -> 0.36953381 | V54: =N54/K54 -> 0.099183191 | W54: =P54/K54 -> 0.49295325 | X54: =Q54/K54 -> 0.11699222 | Y54: =I54-J54 -> 106687.01 | Z54: =_4_1_Synthese_toutes_energies_2026_04[[#This Row],[5, Emissions CO2]]/_4_1_Synthese_toutes_energies_2026_04[[#This Row],[4, Conso totale]] -> 0.11699222
A55: 2018-08 | B55: 95165.957 | C55: 0 | D55: 763.393 | E55: 62.211 | F55: 87546.408 | G55: 6793.945 | H55: =SUM(F55,G55) -> 94340.353 | I55: 141101.12 | J55: 26783.851 | K55: 188132.25 | L55: 7172.327 | M55: 74630.33 | N55: 16345.485 | O55: =SUM(L55,M55,N55) -> 98148.142 | P55: 89984.106 | Q55: 22538.203 | R55: 49.806 | S55: =LEFT(A55,4)*1 -> 2018 | T55: =RIGHT(A55,2)*1 -> 8 | U55: =M55/K55 -> 0.39669079 | V55: =N55/K55 -> 0.086882952 | W55: =P55/K55 -> 0.4783024 | X55: =Q55/K55 -> 0.11979979 | Y55: =I55-J55 -> 114317.27 | Z55: =_4_1_Synthese_toutes_energies_2026_04[[#This Row],[5, Emissions CO2]]/_4_1_Synthese_toutes_energies_2026_04[[#This Row],[4, Conso totale]] -> 0.11979979
A56: 2018-07 | B56: 104530.77 | C56: 0 | D56: 767.01 | E56: 57.78 | F56: 95721.776 | G56: 7984.209 | H56: =SUM(F56,G56) -> 103705.99 | I56: 141596.85 | J56: 28869.591 | K56: 201130.01 | L56: 8566.714 | M56: 77346.967 | N56: 17773.32 | O56: =SUM(L56,M56,N56) -> 103687 | P56: 97443.007 | Q56: 23823.974 | R56: 49.871 | S56: =LEFT(A56,4)*1 -> 2018 | T56: =RIGHT(A56,2)*1 -> 7 | U56: =M56/K56 -> 0.38456204 | V56: =N56/K56 -> 0.088367321 | W56: =P56/K56 -> 0.48447772 | X56: =Q56/K56 -> 0.11845062 | Y56: =I56-J56 -> 112727.26 | Z56: =_4_1_Synthese_toutes_energies_2026_04[[#This Row],[5, Emissions CO2]]/_4_1_Synthese_toutes_energies_2026_04[[#This Row],[4, Conso totale]] -> 0.11845062
A57: 2018-06 | B57: 102667.85 | C57: 0 | D57: 757.729 | E57: 57.839 | F57: 91391.126 | G57: 10461.153 | H57: =SUM(F57,G57) -> 101852.28 | I57: 134963.15 | J57: 27484.277 | K57: 194106.69 | L57: 7520.518 | M57: 76065.633 | N57: 16270.406 | O57: =SUM(L57,M57,N57) -> 99856.557 | P57: 94250.132 | Q57: 22899.856 | R57: 49.721 | S57: =LEFT(A57,4)*1 -> 2018 | T57: =RIGHT(A57,2)*1 -> 6 | U57: =M57/K57 -> 0.39187538 | V57: =N57/K57 -> 0.083821975 | W57: =P57/K57 -> 0.4855584 | X57: =Q57/K57 -> 0.11797562 | Y57: =I57-J57 -> 107478.88 | Z57: =_4_1_Synthese_toutes_energies_2026_04[[#This Row],[5, Emissions CO2]]/_4_1_Synthese_toutes_energies_2026_04[[#This Row],[4, Conso totale]] -> 0.11797562
A58: 2018-05 | B58: 109003.85 | C58: 0 | D58: 762.928 | E58: 56.642 | F58: 97495.218 | G58: 10689.059 | H58: =SUM(F58,G58) -> 108184.28 | I58: 135015 | J58: 32430.082 | K58: 200561.34 | L58: 7235.729 | M58: 73522.893 | N58: 19698.188 | O58: =SUM(L58,M58,N58) -> 100456.81 | P58: 100104.53 | Q58: 23099.889 | R58: 49.517 | S58: =LEFT(A58,4)*1 -> 2018 | T58: =RIGHT(A58,2)*1 -> 5 | U58: =M58/K58 -> 0.36658557 | V58: =N58/K58 -> 0.098215281 | W58: =P58/K58 -> 0.49912176 | X58: =Q58/K58 -> 0.11517618 | Y58: =I58-J58 -> 102584.92 | Z58: =_4_1_Synthese_toutes_energies_2026_04[[#This Row],[5, Emissions CO2]]/_4_1_Synthese_toutes_energies_2026_04[[#This Row],[4, Conso totale]] -> 0.11517618
A59: 2018-04 | B59: 108602.77 | C59: 0 | D59: 762.928 | E59: 54.208 | F59: 97451.631 | G59: 10334.004 | H59: =SUM(F59,G59) -> 107785.63 | I59: 136660.22 | J59: 28028 | K59: 206761.25 | L59: 7487.074 | M59: 70351.084 | N59: 26947.653 | O59: =SUM(L59,M59,N59) -> 104785.81 | P59: 101975.44 | Q59: 23928.256 | R59: 49.327 | S59: =LEFT(A59,4)*1 -> 2018 | T59: =RIGHT(A59,2)*1 -> 4 | U59: =M59/K59 -> 0.34025275 | V59: =N59/K59 -> 0.13033222 | W59: =P59/K59 -> 0.49320383 | X59: =Q59/K59 -> 0.11572892 | Y59: =I59-J59 -> 108632.22 | Z59: =_4_1_Synthese_toutes_energies_2026_04[[#This Row],[5, Emissions CO2]]/_4_1_Synthese_toutes_energies_2026_04[[#This Row],[4, Conso totale]] -> 0.11572892
A60: 2018-03 | B60: 125314.92 | C60: 0 | D60: 778.047 | E60: 53.86 | F60: 113291.11 | G60: 11191.906 | H60: =SUM(F60,G60) -> 124483.01 | I60: 138986.85 | J60: 27100.148 | K60: 261149.61 | L60: 9016.82 | M60: 78101.5 | N60: 52942.31 | O60: =SUM(L60,M60,N60) -> 140060.63 | P60: 121088.98 | Q60: 31777.415 | R60: 49.246 | S60: =LEFT(A60,4)*1 -> 2018 | T60: =RIGHT(A60,2)*1 -> 3 | U60: =M60/K60 -> 0.29906803 | V60: =N60/K60 -> 0.20272789 | W60: =P60/K60 -> 0.46367667 | X60: =Q60/K60 -> 0.1216828 | Y60: =I60-J60 -> 111886.7 | Z60: =_4_1_Synthese_toutes_energies_2026_04[[#This Row],[5, Emissions CO2]]/_4_1_Synthese_toutes_energies_2026_04[[#This Row],[4, Conso totale]] -> 0.1216828
...

Sheet Statistiques à une variable
A1: Colonne1 | B1: Conso_Totale | C1: Emissions_CO2 | D1: Taux_Independance | E1: Imports_Total
A2: Moyenne | B2: =AVERAGE('4 1 Synthese-toutes-energies 20'!K:K) -> 225622.13 | C2: =AVERAGE('4 1 Synthese-toutes-energies 20'!Q:Q) -> 27021.449 | D2: =AVERAGE('4 1 Synthese-toutes-energies 20'!R:R) -> 49.88865 | E2: =AVERAGE('4 1 Synthese-toutes-energies 20'!I:I) -> 142942.09
A3: Médiane | B3: =MEDIAN('4 1 Synthese-toutes-energies 20'!K:K) -> 218248.98 | C3: =MEDIAN('4 1 Synthese-toutes-energies 20'!Q:Q) -> 26071.409 | D3: =MEDIAN('4 1 Synthese-toutes-energies 20'!R:R) -> 49.987 | E3: =MEDIAN('4 1 Synthese-toutes-energies 20'!I:I) -> 142750.23
A4: Écart-type | B4: =STDEV('4 1 Synthese-toutes-energies 20'!K:K) -> 35604.82 | C4: =STDEV('4 1 Synthese-toutes-energies 20'!Q:Q) -> 4900.6757 | D4: =STDEV('4 1 Synthese-toutes-energies 20'!R:R) -> 1.5528037 | E4: =STDEV('4 1 Synthese-toutes-energies 20'!S:S) -> 4.9110311
A5: Min | B5: =MIN('4 1 Synthese-toutes-energies 20'!K:K) -> 156717.95 | C5: =MIN('4 1 Synthese-toutes-energies 20'!Q:Q) -> 14804.465 | D5: =MIN('4 1 Synthese-toutes-energies 20'!R:R) -> 44.884 | E5: =MIN('4 1 Synthese-toutes-energies 20'!I:I) -> 102095.61
A6: Max | B6: =MAX('4 1 Synthese-toutes-energies 20'!K:K) -> 314157.56 | C6: =MAX('4 1 Synthese-toutes-energies 20'!Q:Q) -> 40714.198 | D6: =MAX('4 1 Synthese-toutes-energies 20'!R:R) -> 53.246 | E6: =MAX('4 1 Synthese-toutes-energies 20'!I:I) -> 189172.5
A7: Etendue | B7: =B6-B5 -> 157439.62 | C7: =C6-C5 -> 25909.733 | D7: =D6-D5 -> 8.362 | E7: =E6-E5 -> 87076.892
A8: Q1 | B8: =QUARTILE('4 1 Synthese-toutes-energies 20'!K:K,1) -> 199935.3 | C8: =QUARTILE('4 1 Synthese-toutes-energies 20'!Q:Q,1) -> 23178.774 | D8: =QUARTILE('4 1 Synthese-toutes-energies 20'!R:R,1) -> 48.661 | E8: =QUARTILE('4 1 Synthese-toutes-energies 20'!I:I,1) -> 131834.29
A9: Q3 | B9: =QUARTILE('4 1 Synthese-toutes-energies 20'!K:K,3) -> 255379.49 | C9: =QUARTILE('4 1 Synthese-toutes-energies 20'!Q:Q,3) -> 30179.593 | D9: =QUARTILE('4 1 Synthese-toutes-energies 20'!R:R,3) -> 50.8425 | E9: =QUARTILE('4 1 Synthese-toutes-energies 20'!I:I,3) -> 154202.08
A10: Coef. de variation | B10: =B4/B2 -> 0.15780731 | C10: =C4/C2 -> 0.18136243 | D10: =D4/D2 -> 0.03112539 | E10: =E4/E2 -> 3.4356787e-05

Sheet Mix énergétique moyen par année
B2: Moyennes
A3: Étiquettes de lignes | B3: Conso charbon | C3: Conso pétrole | D3: Conso gaz | E3: Conso nucléaire + ENR
A4: 2006 | B4: 12218.929 | C4: 83301.722 | D4: 37889.774 | E4: 113783.61
A5: 2007 | B5: 12812.669 | C5: 81814.336 | D5: 36812.327 | E5: 112049.58
A6: 2008 | B6: 11937.465 | C6: 81208.607 | D6: 38010.594 | E6: 113245.27
A7: 2009 | B7: 10024.176 | C7: 77834.986 | D7: 36251.514 | E7: 107286.75
A8: 2010 | B8: 10572.517 | C8: 76709.251 | D8: 40665.557 | E8: 112115.59
A9: 2011 | B9: 8865.2064 | C9: 75255.404 | D9: 35128.693 | E9: 112282.8
A10: 2012 | B10: 9887.226 | C10: 74113.919 | D10: 36647.777 | E10: 110543.02
A11: 2013 | B11: 10493.818 | C11: 73384.397 | D11: 37168.665 | E11: 110861.22
A12: 2014 | B12: 8098.0904 | C12: 71308.002 | D12: 31109.791 | E12: 111952.07
A13: 2015 | B13: 8378.4714 | C13: 72351.266 | D13: 33538.274 | E13: 112307.49
A14: 2016 | B14: 7998.6869 | C14: 72210.386 | D14: 36660.038 | E14: 106009.39
A15: 2017 | B15: 8720.2172 | C15: 72663.979 | D15: 36808.644 | E15: 104333.07
... A20: 2022 | B20: 5622.2667 | C20: 66336.68 | D20: 31775.549 | E20: 84673.646
A21: Total général | B21: 8957.7532 | C21: 73771.996 | D21: 35745.564 | E21: 107164.81
A23: Moyennes totales | B23: Charbon | C23: Pétrole | D23: Gaz | E23: Nucléaire + ENR
B24: =GETPIVOTDATA("Conso charbon",$A$3) -> 8957.7532 | C24: =GETPIVOTDATA("Conso pétrole",$A$3) -> 73771.996 | D24: =GETPIVOTDATA("Conso gaz",$A$3) -> 35745.564 | E24: =GETPIVOTDATA("Conso nucléaire + ENR",$A$3) -> 107164.81

Sheet Emissions CO2
A3: Étiquettes de lignes | B3: Moyenne des émissions CO2 (en kt)
A4: 2006 | B4: 365385.38
A5: 2007 | B5: 359144.88
A6: 2008 | B6: 359636.73
A7: 2009 | B7: 341974.17
A8: 2010 | B8: 352087.39
A9: 2011 | B9: 326114.66
A10: 2012 | B10: 331894.09
A11: 2013 | B11: 335034.58
A12: 2014 | B12: 303573.27
A13: 2015 | B13: 313317.45
A14: 2016 | B14: 317186.9
A15: 2017 | B15: 322059.09
... A20: 2022 | B20: 286682.47
A21: Total général | B21: 5512375.7

Sheet Import Exports par année
B2: Sommes
A3: Étiquettes de lignes | B3: Imports total (en GWh) | C3: Exports total (en GWh)
A4: 2006 | B4: 2006985.5 | C4: 383231.01
A5: 2007 | B5: 1940772.9 | C5: 366504.07
A6: 2008 | B6: 2010048.9 | C6: 401100.91
A7: 2009 | B7: 1870809.8 | C7: 317527.58
A8: 2010 | B8: 1837908.8 | C8: 318941.43
A9: 2011 | B9: 1796817.6 | C9: 342700.67
A10: 2012 | B10: 1744378.4 | C10: 303051.25
A11: 2013 | B11: 1731394.8 | C11: 286366.62
A12: 2014 | B12: 1633823.9 | C12: 326947.64
A13: 2015 | B13: 1673220.5 | C13: 341633.5
A14: 2016 | B14: 1674874.8 | C14: 311756.35
A15: 2017 | B15: 1702017.3 | C15: 333024.79
... A20: 2022 | B20: 1481204.3 | C20: 264714.14
A21: Total général | B21: 29017245 | C21: 5455811

Sheet Statistiques à deux variables
A1: Colonne1 | B1: Consommation totale - Emission CO2 | C1: Consommation fossiles - CO2 | D1: Production nucléaire + ENR - Indépendance
A2: Coefficient de correlation | B2: =CORREL('4 1 Synthese-toutes-energies 20'!K:K,'4 1 Synthese-toutes-energies 20'!Q:Q) -> 0.96603668 | C2: =CORREL('4 1 Synthese-toutes-energies 20'!O:O,'4 1 Synthese-toutes-energies 20'!Q:Q) -> 0.99686605 | D2: =CORREL('4 1 Synthese-toutes-energies 20'!H:H,'4 1 Synthese-toutes-energies 20'!R:R) -> 0.19243326
A3: Coefficient de détermination | B3: =RSQ('4 1 Synthese-toutes-energies 20'!Q:Q,'4 1 Synthese-toutes-energies 20'!K:K) -> 0.93322687 | D3: =RSQ('4 1 Synthese-toutes-energies 20'!R:R,'4 1 Synthese-toutes-energies 20'!H:H) -> 0.037030558
A4: Pente de la droite | B4: =SLOPE('4 1 Synthese-toutes-energies 20'!Q:Q,'4 1 Synthese-toutes-energies 20'!K:K) -> 0.13296606 | D4: =SLOPE('4 1 Synthese-toutes-energies 20'!R:R,'4 1 Synthese-toutes-energies 20'!H:H) -> 1.8647817e-05
A5: Ordonnée à l'origine | B5: =INTERCEPT('4 1 Synthese-toutes-energies 20'!Q:Q,'4 1 Synthese-toutes-energies 20'!K:K) -> -2978.6349 | D5: =INTERCEPT('4 1 Synthese-toutes-energies 20'!R:R,'4 1 Synthese-toutes-energies 20'!H:H) -> 47.819015
