Workbook

Sheet _4_2_Synthese_Electricite_2026_
A1: Column1 | B1: Column2 | C1: Column3 | D1: Column4 | E1: Column5 | F1: Column6 | G1: Column7 | H1: Column8 | I1: Column9 | J1: Column10 | K1: Column11 | L1: Column12 | M1: Column13 | N1: Column14
A2: Période | B2: 1. Production (brute) d'électricité hydraulique, éolienne et photovoltaïque (en GWh) | C2: 1.1 Production brute d'électricité hydraulique (en GWh) | D2: 1.2 Production brute d'électricité éolienne (en GWh) | E2: 1.3 Production brute d'électricité solaire photovoltaïque (en GWh) | F2: 2. Production nucléaire (équivalent primaire à la production, sous forme de chaleur) (en GWh) | G2: 3. Solde importateur (importations - exportations) d'électricité (en GWh) | H2: 3.1 Importations d'électricité (en GWh) | I2: 3.2 Exportations d'électricité (en GWh) | J2: 4. Consommation primaire d'énergie nucléaire, hydraulique, éolienne et photovoltaïque brute (en GWh) | K2: 5. Consommation d'électricité primaire et d'équivalent primaire d'électricité nucléaire CVC-CJO (en GWh) | L2: 6. Consommation d'électricité primaire et d'équivalent primaire d'électricité nucléaire CVS-CVC-CJO (en GWh) | M2: 7. Degrés jours unifiés mensuels en France, pour la période de chauffe (vaut 0 de juin à septembre, en °C) | N2: 8. Indice de rigueur climatique pour la France métropolitaine (ref.1 pour la période de référence) (sans unité)
A3: PERIODE | B3: PRODB_ELE_SYNT | C3: PRODB_HYDRO_SYNT | D3: PRODB_EOL_SYNT | E3: PRODB_PV_SYNT | F3: PRODB_NUCL_SYNT | G3: QSOLI_ELE_SYNT | H3: QIMP_ELE_SYNT | I3: QEXP_ELE_SYNT | J3: CONSO_ELE_SYNT | K3: CONSO_ELE_SYNT_COR1 | L3: CONSO_ELE_SYNT_COR2 | M3: DJU | N3: INDRIG
A4: 2026-02 | B4: 14728.307 | C4: 6530.276 | D4: 6511.472 | E4: 1686.559 | F4: 101210.84 | G4: -8546.592 | H4: 1155.744 | I4: 9702.335 | J4: 107392.555 | K4: 111117.937 | L4: 103171.582 | M4: 164.5 | N4: 0.638
A5: 2026-01 | B5: 13743.982 | C5: 6415.77 | D5: 6163.672 | E5: 1164.54 | F5: 120977.946 | G5: -6450.831 | H5: 1998.12 | I5: 8448.951 | J5: 128271.097 | K5: 128723.757 | L5: 102274.31 | M5: 300.7 | N5: 0.964
A6: 2025-12 | B6: 13619.297 | C6: 6557.591 | D6: 5944.041 | E6: 1117.664 | F6: 122374.567 | G6: -10671.542 | H6: 730.876 | I6: 11402.418 | J6: 125322.322 | K6: 127013.777 | L6: 107919.751 | M6: 245.6 | N6: 0.855
A7: 2025-11 | B7: 13063.459 | C7: 5986.831 | D7: 5514.904 | E7: 1561.724 | F7: 106352.443 | G7: -9121.631 | H7: 920.313 | I7: 10041.944 | J7: 110294.272 | K7: 111090.968 | L7: 106372.71 | M7: 177.1 | N7: 0.904
A8: 2025-10 | B8: 12412.642 | C8: 4307.534 | D8: 5523.829 | E8: 2581.279 | F8: 96519.121 | G8: -8745.68 | H8: 632.138 | I8: 9377.818 | J8: 100186.083 | K8: 101205.852 | L8: 103347.395 | M8: 64.7 | N8: 0.872
A9: 2025-09 | B9: 10824.239 | C9: 3771.678 | D9: 3988.734 | E9: 3063.827 | F9: 93113.391 | G9: -8706.709 | H9: 564.275 | I9: 9270.984 | J9: 95230.921 | K9: 95373.018 | L9: 105596.512 | M9: 0 | N9: 1
A10: 2025-08 | B10: 10202.807 | C10: 3499.762 | D10: 2646.361 | E10: 4056.684 | F10: 91590.718 | G10: -8793.19 | H10: 705.141 | I10: 9498.331 | J10: 93000.335 | K10: 91929.192 | L10: 104329.141 | M10: 0 | N10: 1
A11: 2025-07 | B11: 11346.493 | C11: 3867.243 | D11: 2921.78 | E11: 4557.471 | F11: 94358.878 | G11: -8983.518 | H11: 663.078 | I11: 9646.597 | J11: 96721.853 | K11: 97040.016 | L11: 106865.69 | M11: 0 | N11: 1
A12: 2025-06 | B12: 11891.865 | C12: 5367.633 | D12: 2471.821 | E12: 4052.41 | F12: 83035.331 | G12: -7103.715 | H12: 807.991 | I12: 7911.706 | J12: 87823.481 | K12: 86479.742 | L12: 101927.152 | M12: 0 | N12: 1
... A185: 2011-01 | B185: 7320.55 | C185: 6048.917 | D185: 1229.221 | E185: 42.411 | F185: 138909.815 | G185: -3750.675 | H185: 1266.228 | I185: 5016.903 | J185: 142479.69 | K185: 141886.171 | L185: 112664.923 | M185: 322.1 | N185: 1.033
A186: 2010-12 | B186: 8014.061 | C186: 7063.89 | D186: 950.171 | E186: 0 | F186: 132842.122 | G186: -830.149 | H186: 2184.393 | I186: 3014.543 | J186: 140026.034 | L186: 114433.782 | M186: 408.2 | N186: 1.421
A187: 2010-11 | B187: 6489.117 | C187: 5519.942 | D187: 969.174 | E187: 0 | F187: 112760.297 | G187: -2321.418 | H187: 1726.311 | I187: 4047.728 | J187: 116927.996 | L187: 113184.067 | M187: 224.6 | N187: 1.147
A188: 2010-10 | B188: 5083.066 | C188: 4048.88 | D188: 1034.186 | E188: 0 | F188: 101708.371 | G188: -569.102 | H188: 2680.482 | I188: 3249.585 | J188: 106222.335 | L188: 108614.222 | M188: 114.8 | N188: 1.547
A189: 2010-09 | B189: 4156.318 | C189: 3608.219 | D189: 548.099 | E189: 0 | F189: 100872.091 | G189: -3610.65 | H189: 982.177 | I189: 4592.827 | J189: 101417.759 | L189: 112298.626 | M189: 0 | N189: 1
A190: 2010-08 | B190: 5070.815 | C190: 4402.695 | D190: 668.12 | E190: 0 | F190: 103451.927 | G190: -5908.063 | H190: 481.087 | I190: 6389.15 | J190: 102614.679 | L190: 113600.542 | M190: 0 | N190: 1
A191: 2010-07 | B191: 5991.1 | C191: 5512.014 | D191: 479.086 | E191: 0 | F191: 101295.785 | G191: -4632.834 | H191: 781.141 | I191: 5413.974 | J191: 102654.051 | L191: 112363.767 | M191: 0 | N191: 1
A192: 2010-06 | B192: 7974.2 | C192: 7408.098 | D192: 566.102 | E192: 0 | F192: 94335.046 | G192: -5287.952 | H192: 544.098 | I192: 5832.05 | J192: 97021.295 | L192: 110718.364 | M192: 0 | N192: 1
A193: 2010-05 | B193: 7299.991 | C193: 6574.861 | D193: 725.131 | E193: 0 | F193: 93362.235 | G193: -2139.385 | H193: 1377.248 | I193: 3516.633 | J193: 98522.841 | L193: 108020.322 | M193: 89.9 | N193: 1.92
A194: 2010-04 | B194: 6541.318 | C194: 5834.191 | D194: 707.127 | E194: 0 | F194: 99668.426 | G194: -2590.466 | H194: 1312.236 | I194: 3902.702 | J194: 103619.278 | L194: 108251.023 | M194: 116.6 | N194: 0.994
A195: 2010-03 | B195: 7459.857 | C195: 6310.65 | D195: 1149.207 | E195: 0 | F195: 114382.671 | G195: -2146.386 | H195: 2129.383 | I195: 4275.77 | J195: 119696.141 | L195: 110449.04 | M195: 236 | N195: 1.177
A196: 2010-02 | B196: 6852.716 | C196: 5903.545 | D196: 949.171 | E196: 0 | F196: 115196.484 | G196: -1095.197 | H196: 2199.396 | I196: 3294.593 | J196: 120954.003 | L196: 111949.064 | M196: 301.7 | N196: 1.17
A197: 2010-01 | B197: 7039.828 | C197: 6371.707 | D197: 668.12 | E197: 0 | F197: 128292.756 | G197: 378.068 | H197: 3042.548 | I197: 2664.48 | J197: 135710.651 | L197: 108893.223 | M197: 415.5 | N197: 1.332
... A437: 1990-01 | B437: 3180.521 | C437: 3180.521 | D437: 0 | E437: 0 | F437: 87182.585 | G437: -2019.363 | H437: 1045.188 | I437: 3064.552 | J437: 88343.743 | L437: 70937.044 | M437: 296.8 | N437: 0.951
A438: 1989-12 | B438: 3524.799 | C438: 3524.799 | D438: 0 | E438: 0 | F438: 84327.017 | G438: -1466.264 | H438: 1853.334 | I438: 3319.597 | J438: 86385.552 | M438: 339.945 | N438: 0.963
A439: 1989-11 | B439: 4312.588 | C439: 4312.588 | D439: 0 | E439: 0 | F439: 75262.58 | G439: -3461.623 | H439: 871.157 | I439: 4332.78 | J439: 76113.545 | M439: 288.146 | N439: 1.134
A440: 1989-10 | B440: 2770.425 | C440: 2770.425 | D440: 0 | E440: 0 | F440: 74541.509 | G440: -3868.696 | H440: 721.13 | I440: 4589.826 | J440: 73443.238 | M440: 96.957 | N440: 0.779
A441: 1989-09 | B441: 2887.885 | C441: 2887.885 | D441: 0 | E441: 0 | F441: 68536.839 | G441: -3339.601 | H441: 686.123 | I441: 4025.724 | J441: 68085.122 | M441: 0 | N441: 1
A442: 1989-08 | B442: 3623.019 | C442: 3623.019 | D442: 0 | E442: 0 | F442: 64835.766 | G442: -3014.543 | H442: 614.111 | I442: 3628.653 | J442: 65444.243 | M442: 0 | N442: 1
A443: 1989-07 | B443: 4519.155 | C443: 4519.155 | D443: 0 | E443: 0 | F443: 71513.649 | G443: -3698.666 | H443: 524.094 | I443: 4222.76 | J443: 72334.138 | M443: 0 | N443: 1
A444: 1989-06 | B444: 4606.237 | C444: 4606.237 | D444: 0 | E444: 0 | F444: 74346.884 | G444: -3993.719 | H444: 347.062 | I444: 4340.781 | J444: 74959.402 | M444: 0 | N444: 1
A445: 1989-05 | B445: 6771.137 | C445: 6771.137 | D445: 0 | E445: 0 | F445: 68122.063 | G445: -4114.741 | H445: 420.076 | I445: 4534.816 | J445: 70778.46 | M445: 48.047 | N445: 0.612
A446: 1989-04 | B446: 6138.273 | C446: 6138.273 | D446: 0 | E446: 0 | F446: 80048.45 | G446: -3861.695 | H446: 448.081 | I446: 4309.776 | J446: 82325.028 | M446: 234.175 | N446: 1.41
A447: 1989-03 | B447: 5095.314 | C447: 5095.314 | D447: 0 | E447: 0 | F447: 84579.072 | G447: -4082.735 | H447: 380.068 | I447: 4462.803 | J447: 85591.652 | M447: 209.531 | N447: 0.819
A448: 1989-02 | B448: 2946.614 | C448: 2946.614 | D448: 0 | E448: 0 | F448: 82285.046 | G448: -3395.611 | H448: 529.095 | I448: 3924.706 | J448: 81836.049 | M448: 303.151 | N448: 0.948
A449: 1989-01 | B449: 3620.994 | C449: 3620.994 | D449: 0 | E449: 0 | F449: 92769.29 | G449: -3865.696 | H449: 712.128 | I449: 4577.824 | J449: 92524.588 | M449: 384.477 | N449: 1.036
... A545: 1981-01 | B545: 6329.652 | C545: 6329.652 | D545: 0 | E545: 0 | F545: 28435.686 | G545: -382.069 | H545: 1216.219 | I545: 1598.288 | J545: 34383.269 | M545: 407.494 | N545: 1.098
A546: 1980-12 | M546: 423.706 | N546: 1.201
...

Sheet Production
A1: Période | B1: Hydraulique | C1: Éolien | D1: Solaire | E1: Nucléaire | F1: Nucléaire_Elec | G1: Année | H1: Mois | I1: Total_EnR | J1: Total_Production | K1: Part_Nucléaire en % | L1: Part_EnR en %
A2: 2022-12 | B2: 5234.522 | C2: 4364.634 | D2: 604.497 | E2: =89307.744 -> 89307.744 | F2: =E2/3 -> 29769.248 | G2: =LEFT(A2,4)*1 -> 2022 | H2: =RIGHT(A2,2)*1 -> 12 | I2: =SUM($B2,$C2,$D2) -> 10203.653 | J2: =SUM($B2,$C2,$D2,$F2) -> 39972.901 | K2: =F2 / J2 -> 0.74473574 | L2: =I2 / J2 -> 0.25526426
A3: 2022-11 | B3: 3949.045 | C3: 4626.758 | D3: 848.824 | E3: 69562.288 | F3: =E3/3 -> 23187.429 | G3: =LEFT(A3,4)*1 -> 2022 | H3: =RIGHT(A3,2)*1 -> 11 | I3: =SUM($B3,$C3,$D3) -> 9424.627 | J3: =SUM($B3,$C3,$D3,$F3) -> 32612.056 | K3: =F3 / J3 -> 0.71100789 | L3: =I3 / J3 -> 0.28899211
A4: 2022-10 | B4: 3152.902 | C4: 3432.376 | D4: 1319.37 | E4: 65057.226 | F4: =E4/3 -> 21685.742 | G4: =LEFT(A4,4)*1 -> 2022 | H4: =RIGHT(A4,2)*1 -> 10 | I4: =SUM($B4,$C4,$D4) -> 7904.648 | J4: =SUM($B4,$C4,$D4,$F4) -> 29590.39 | K4: =F4 / J4 -> 0.73286435 | L4: =I4 / J4 -> 0.26713565
A5: 2022-09 | B5: 2541.154 | C5: 2293.837 | D5: 1838.609 | E5: 58600.02 | F5: =E5/3 -> 19533.34 | G5: =LEFT(A5,4)*1 -> 2022 | H5: =RIGHT(A5,2)*1 -> 9 | I5: =SUM($B5,$C5,$D5) -> 6673.6 | J5: =SUM($B5,$C5,$D5,$F5) -> 26206.94 | K5: =F5 / J5 -> 0.7453499 | L5: =I5 / J5 -> 0.2546501
A6: 2022-08 | B6: 2778.709 | C6: 2077.602 | D6: 2302.854 | E6: 58554.054 | F6: =E6/3 -> 19518.018 | G6: =LEFT(A6,4)*1 -> 2022 | H6: =RIGHT(A6,2)*1 -> 8 | I6: =SUM($B6,$C6,$D6) -> 7159.165 | J6: =SUM($B6,$C6,$D6,$F6) -> 26677.183 | K6: =F6 / J6 -> 0.73163714 | L6: =I6 / J6 -> 0.26836286
A7: 2022-07 | B7: 3588.929 | C7: 1885.33 | D7: 2592.237 | E7: 60385.593 | F7: =E7/3 -> 20128.531 | G7: =LEFT(A7,4)*1 -> 2022 | H7: =RIGHT(A7,2)*1 -> 7 | I7: =SUM($B7,$C7,$D7) -> 8066.496 | J7: =SUM($B7,$C7,$D7,$F7) -> 28195.027 | K7: =F7 / J7 -> 0.71390359 | L7: =I7 / J7 -> 0.28609641
A8: 2022-06 | B8: 4157.178 | C8: 1849.939 | D8: 2230.207 | E8: 64482.038 | F8: =E8/3 -> 21494.013 | G8: =LEFT(A8,4)*1 -> 2022 | H8: =RIGHT(A8,2)*1 -> 6 | I8: =SUM($B8,$C8,$D8) -> 8237.324 | J8: =SUM($B8,$C8,$D8,$F8) -> 29731.337 | K8: =F8 / J8 -> 0.72294135 | L8: =I8 / J8 -> 0.27705865
A9: 2022-05 | B9: 5157.255 | C9: 2076.276 | D9: 2263.87 | E9: 65809.978 | F9: =E9/3 -> 21936.659 | G9: =LEFT(A9,4)*1 -> 2022 | H9: =RIGHT(A9,2)*1 -> 5 | I9: =SUM($B9,$C9,$D9) -> 9497.401 | J9: =SUM($B9,$C9,$D9,$F9) -> 31434.06 | K9: =F9 / J9 -> 0.69786274 | L9: =I9 / J9 -> 0.30213726
A10: 2022-04 | B10: 5231.089 | C10: 3560.29 | D10: 1795.845 | E10: 69785.579 | F10: =E10/3 -> 23261.86 | G10: =LEFT(A10,4)*1 -> 2022 | H10: =RIGHT(A10,2)*1 -> 4 | I10: =SUM($B10,$C10,$D10) -> 10587.224 | J10: =SUM($B10,$C10,$D10,$F10) -> 33849.084 | K10: =F10 / J10 -> 0.68722273 | L10: =I10 / J10 -> 0.31277727
A11: 2022-03 | B11: 4712.432 | C11: 3461.02 | D11: 1390.713 | E11: 85750.867 | F11: =E11/3 -> 28583.622 | G11: =LEFT(A11,4)*1 -> 2022 | H11: =RIGHT(A11,2)*1 -> 3 | I11: =SUM($B11,$C11,$D11) -> 9564.165 | J11: =SUM($B11,$C11,$D11,$F11) -> 38147.787 | K11: =F11 / J11 -> 0.74928651 | L11: =I11 / J11 -> 0.25071349
A12: 2022-02 | B12: 4511.357 | C12: 5265.783 | D12: 1029.124 | E12: 94127.124 | F12: =E12/3 -> 31375.708 | G12: =LEFT(A12,4)*1 -> 2022 | H12: =RIGHT(A12,2)*1 -> 2 | I12: =SUM($B12,$C12,$D12) -> 10806.264 | J12: =SUM($B12,$C12,$D12,$F12) -> 42181.972 | K12: =F12 / J12 -> 0.74381795 | L12: =I12 / J12 -> 0.25618205
A13: 2022-01 | B13: 6075.32 | C13: 3144.953 | D13: 784.956 | E13: 111862.4 | F13: =E13/3 -> 37287.467 | G13: =LEFT(A13,4)*1 -> 2022 | H13: =RIGHT(A13,2)*1 -> 1 | I13: =SUM($B13,$C13,$D13) -> 10005.229 | J13: =SUM($B13,$C13,$D13,$F13) -> 47292.696 | K13: =F13 / J13 -> 0.78844029 | L13: =I13 / J13 -> 0.21155971
A14: 2021-12 | B14: 5461.218 | C14: 4331.128 | D14: 588.286 | E14: 100376.85 | F14: =E14/3 -> 33458.95 | G14: =LEFT(A14,4)*1 -> 2021 | H14: =RIGHT(A14,2)*1 -> 12 | I14: =SUM($B14,$C14,$D14) -> 10380.632 | J14: =SUM($B14,$C14,$D14,$F14) -> 43839.582 | K14: =F14 / J14 -> 0.76321326 | L14: =I14 / J14 -> 0.23678674
... A145: 2011-01 | B145: 6048.917 | C145: 1229.221 | D145: 42.411 | E145: 138909.82 | F145: =E145/3 -> 46303.272 | G145: =LEFT(A145,4)*1 -> 2011 | H145: =RIGHT(A145,2)*1 -> 1 | I145: =SUM($B145,$C145,$D145) -> 7320.549 | J145: =SUM($B145,$C145,$D145,$F145) -> 53623.821 | K145: =F145 / J145 -> 0.86348326 | L145: =I145 / J145 -> 0.13651674
A146: 2010-12 | B146: 7063.89 | C146: 950.171 | D146: 0 | E146: 132842.12 | F146: =E146/3 -> 44280.707 | G146: =LEFT(A146,4)*1 -> 2010 | H146: =RIGHT(A146,2)*1 -> 12 | I146: =SUM($B146,$C146,$D146) -> 8014.061 | J146: =SUM($B146,$C146,$D146,$F146) -> 52294.768 | K146: =F146 / J146 -> 0.84675215 | L146: =I146 / J146 -> 0.15324785
A147: 2010-11 | B147: 5519.942 | C147: 969.174 | D147: 0 | E147: 112760.3 | F147: =E147/3 -> 37586.766 | G147: =LEFT(A147,4)*1 -> 2010 | H147: =RIGHT(A147,2)*1 -> 11 | I147: =SUM($B147,$C147,$D147) -> 6489.116 | J147: =SUM($B147,$C147,$D147,$F147) -> 44075.882 | K147: =F147 / J147 -> 0.85277399 | L147: =I147 / J147 -> 0.14722601
A148: 2010-10 | B148: 4048.88 | C148: 1034.186 | D148: 0 | E148: 101708.37 | F148: =E148/3 -> 33902.79 | G148: =LEFT(A148,4)*1 -> 2010 | H148: =RIGHT(A148,2)*1 -> 10 | I148: =SUM($B148,$C148,$D148) -> 5083.066 | J148: =SUM($B148,$C148,$D148,$F148) -> 38985.856 | K148: =F148 / J148 -> 0.86961769 | L148: =I148 / J148 -> 0.13038231
A149: 2010-09 | B149: 3608.219 | C149: 548.099 | D149: 0 | E149: 100872.09 | F149: =E149/3 -> 33624.03 | G149: =LEFT(A149,4)*1 -> 2010 | H149: =RIGHT(A149,2)*1 -> 9 | I149: =SUM($B149,$C149,$D149) -> 4156.318 | J149: =SUM($B149,$C149,$D149,$F149) -> 37780.348 | K149: =F149 / J149 -> 0.8899873 | L149: =I149 / J149 -> 0.1100127
A150: 2010-08 | B150: 4402.695 | C150: 668.12 | D150: 0 | E150: 103451.93 | F150: =E150/3 -> 34483.976 | G150: =LEFT(A150,4)*1 -> 2010 | H150: =RIGHT(A150,2)*1 -> 8 | I150: =SUM($B150,$C150,$D150) -> 5070.815 | J150: =SUM($B150,$C150,$D150,$F150) -> 39554.791 | K150: =F150 / J150 -> 0.87180276 | L150: =I150 / J150 -> 0.12819724
A151: 2010-07 | B151: 5512.014 | C151: 479.086 | D151: 0 | E151: 101295.79 | F151: =E151/3 -> 33765.262 | G151: =LEFT(A151,4)*1 -> 2010 | H151: =RIGHT(A151,2)*1 -> 7 | I151: =SUM($B151,$C151,$D151) -> 5991.1 | J151: =SUM($B151,$C151,$D151,$F151) -> 39756.362 | K151: =F151 / J151 -> 0.84930462 | L151: =I151 / J151 -> 0.15069538
A152: 2010-06 | B152: 7408.098 | C152: 566.102 | D152: 0 | E152: 94335.046 | F152: =E152/3 -> 31445.015 | G152: =LEFT(A152,4)*1 -> 2010 | H152: =RIGHT(A152,2)*1 -> 6 | I152: =SUM($B152,$C152,$D152) -> 7974.2 | J152: =SUM($B152,$C152,$D152,$F152) -> 39419.215 | K152: =F152 / J152 -> 0.79770779 | L152: =I152 / J152 -> 0.20229221
A153: 2010-05 | B153: 6574.861 | C153: 725.131 | D153: 0 | E153: 93362.235 | F153: =E153/3 -> 31120.745 | G153: =LEFT(A153,4)*1 -> 2010 | H153: =RIGHT(A153,2)*1 -> 5 | I153: =SUM($B153,$C153,$D153) -> 7299.992 | J153: =SUM($B153,$C153,$D153,$F153) -> 38420.737 | K153: =F153 / J153 -> 0.80999865 | L153: =I153 / J153 -> 0.19000135
A154: 2010-04 | B154: 5834.191 | C154: 707.127 | D154: 0 | E154: 99668.426 | F154: =E154/3 -> 33222.809 | G154: =LEFT(A154,4)*1 -> 2010 | H154: =RIGHT(A154,2)*1 -> 4 | I154: =SUM($B154,$C154,$D154) -> 6541.318 | J154: =SUM($B154,$C154,$D154,$F154) -> 39764.127 | K154: =F154 / J154 -> 0.835497 | L154: =I154 / J154 -> 0.164503
A155: 2010-03 | B155: 6310.65 | C155: 1149.207 | D155: 0 | E155: 114382.67 | F155: =E155/3 -> 38127.557 | G155: =LEFT(A155,4)*1 -> 2010 | H155: =RIGHT(A155,2)*1 -> 3 | I155: =SUM($B155,$C155,$D155) -> 7459.857 | J155: =SUM($B155,$C155,$D155,$F155) -> 45587.414 | K155: =F155 / J155 -> 0.83636148 | L155: =I155 / J155 -> 0.16363852
A156: 2010-02 | B156: 5903.545 | C156: 949.171 | D156: 0 | E156: 115196.48 | F156: =E156/3 -> 38398.828 | G156: =LEFT(A156,4)*1 -> 2010 | H156: =RIGHT(A156,2)*1 -> 2 | I156: =SUM($B156,$C156,$D156) -> 6852.716 | J156: =SUM($B156,$C156,$D156,$F156) -> 45251.544 | K156: =F156 / J156 -> 0.84856393 | L156: =I156 / J156 -> 0.15143607
A157: 2010-01 | B157: 6371.707 | C157: 668.12 | D157: 0 | E157: 128292.76 | F157: =E157/3 -> 42764.252 | G157: =LEFT(A157,4)*1 -> 2010 | H157: =RIGHT(A157,2)*1 -> 1 | I157: =SUM($B157,$C157,$D157) -> 7039.827 | J157: =SUM($B157,$C157,$D157,$F157) -> 49804.079 | K157: =F157 / J157 -> 0.85864959 | L157: =I157 / J157 -> 0.14135041
... A205: 2006-01 | B205: 4303.729 | C205: 129.023 | D205: 0 | E205: 135581.95 | F205: =E205/3 -> 45193.982 | G205: =LEFT(A205,4)*1 -> 2006 | H205: =RIGHT(A205,2)*1 -> 1 | I205: =SUM($B205,$C205,$D205) -> 4432.752 | J205: =SUM($B205,$C205,$D205,$F205) -> 49626.734 | K205: =F205 / J205 -> 0.91067814 | L205: =I205 / J205 -> 0.089321857

Sheet Stats_1var
A1: Stats | B1: Hydraulique | C1: Éolien | D1: Solaire | E1: Nucléaire
A2: Moyenne | B2: =AVERAGE(Production!B:B) -> 5285.4583 | C2: =AVERAGE(Production!C:C) -> 1597.5216 | D2: =AVERAGE(Production!D:D) -> 753.20819 | E2: =AVERAGE(Production!F:F) -> 34537.203
A3: Médiane | B3: =MEDIAN(Production!B:B) -> 5263.8815 | C3: =MEDIAN(Production!C:C) -> 1302.405 | D3: =MEDIAN(Production!D:D) -> 628.8155 | E3: =MEDIAN(Production!F:F) -> 33855.58
A4: Écart-type | B4: =_xlfn.STDEV.P(Production!B:B) -> 1366.0347 | C4: =_xlfn.STDEV.P(Production!C:C) -> 1191.8879 | D4: =_xlfn.STDEV.P(Production!D:D) -> 530.62223 | E4: =_xlfn.STDEV.P(Production!F:F) -> 5339.3399
A5: Variance | B5: =_xlfn.VAR.P(Production!B:B) -> 1866050.7 | C5: =_xlfn.VAR.P(Production!C:C) -> 1420596.7 | D5: =_xlfn.VAR.P(Production!D:D) -> 281559.95 | E5: =_xlfn.VAR.P(Production!F:F) -> 28508550
A6: Min | B6: =MIN(Production!B:B) -> 2541.154 | C6: =MIN(Production!C:C) -> 94.017 | D6: =MIN(Production!D:D) -> 42.411 | E6: =MIN(Production!F:F) -> 19518.018
A7: Max | B7: =MAX(Production!B:B) -> 8578.86 | C7: =MAX(Production!C:C) -> 5907.95 | D7: =MAX(Production!D:D) -> 2592.237 | E7: =MAX(Production!F:F) -> 46303.272
A8: Étendue | B8: =MAX(Production!B:B)-MIN(Production!B:B) -> 6037.706 | C8: =MAX(Production!C:C)-MIN(Production!C:C) -> 5813.933 | D8: =MAX(Production!D:D)-MIN(Production!D:D) -> 2549.826 | E8: =MAX(Production!F:F)-MIN(Production!F:F) -> 26785.254
A9: Q1 | B9: =_xlfn.QUARTILE.INC(Production!B:B,1) -> 4117.0775 | C9: =_xlfn.QUARTILE.INC(Production!C:C,1) -> 675.878 | D9: =_xlfn.QUARTILE.INC(Production!D:D,1) -> 330.95375 | E9: =_xlfn.QUARTILE.INC(Production!F:F,1) -> 31205.444
A10: Q3 | B10: =_xlfn.QUARTILE.INC(Production!B:B,3) -> 6410.3027 | C10: =_xlfn.QUARTILE.INC(Production!C:C,3) -> 2189.6943 | D10: =_xlfn.QUARTILE.INC(Production!D:D,3) -> 1052.086 | E10: =_xlfn.QUARTILE.INC(Production!F:F,3) -> 38242.48
A11: Écart interquartile | B11: =B10-B9 -> 2293.2252 | C11: =C10-C9 -> 1513.8162 | D11: =D10-D9 -> 721.13225 | E11: =E10-E9 -> 7037.0358
A12: Coef. de variation | B12: =B4/B2 -> 0.25845151 | C12: =C4/C2 -> 0.74608561 | D12: =D4/D2 -> 0.70448281 | E12: =E4/E2 -> 0.15459676

Sheet Saisonnalite
A3: Moyenne de Hydraulique | B3: Étiquettes de colonnes
A4: Étiquettes de lignes | B4: 2006 | C4: 2007 | D4: 2008 | E4: 2009 | F4: 2010 | G4: 2011 | H4: 2012 | I4: 2013 | J4: 2014 | K4: 2015 | L4: 2016 | M4: 2017 | N4: 2018 | O4: 2019 | P4: 2020 | Q4: 2021 | R4: 2022 | S4: Total général
A5: 1 | B5: 4303.729 | C5: 5470.186 | D5: 6132.561 | E5: 6149.193 | F5: 6371.707 | G5: 6048.917 | H5: 6833.247 | I5: 6890.277 | J5: 7053.083 | K5: 6236.844 | L5: 5731.961 | M5: 5286.67 | N5: 7523.848 | O5: 5146.742 | P5: 6472.11 | Q5: 7493.704 | R5: 6075.32 | S5: 6189.4176
A6: 2 | B6: 4666.944 | C6: 5648.301 | D6: 4503.822 | E6: 5808.399 | F6: 5903.545 | G6: 4119.895 | H6: 5250.793 | I6: 6870.56 | J6: 7112.365 | K6: 6423.175 | L6: 7016.748 | M6: 4583.539 | N6: 7367.189 | O6: 5202.466 | P6: 6432.001 | Q6: 7057.552 | R6: 4511.357 | S6: 5792.8618
A7: 3 | B7: 6711.851 | C7: 6929.66 | D7: 5672.885 | E7: 6315.072 | F7: 6310.65 | G7: 4525.639 | H7: 4001.282 | I7: 6473.443 | J7: 7065.438 | K7: 6525.108 | L7: 6684.654 | M7: 6308.38 | N7: 7323.987 | O7: 5309.362 | P7: 7508.621 | Q7: 6089.126 | R7: 4712.432 | S7: 6145.1524
A8: 4 | B8: 7165.018 | C8: 5461.009 | D8: 7152.186 | E8: 6743.059 | F8: 5834.191 | G8: 4130.253 | H8: 5470.697 | I8: 7247.376 | J8: 5905.107 | K8: 5809.624 | L8: 6538.252 | M8: 4239.905 | N8: 7162.382 | O8: 4622.497 | P8: 5225.506 | Q8: 4170.276 | R8: 5231.089 | S8: 5771.0839
A9: 5 | B9: 6901.652 | C9: 6202.868 | D9: 7354.555 | E9: 7209.668 | F9: 6574.861 | G9: 3481.64 | H9: 7847.839 | I9: 8578.86 | J9: 6221.368 | K9: 6515.786 | L9: 6570.149 | M9: 5757.965 | N9: 7938.852 | O9: 5696.605 | P9: 6858.007 | Q9: 6436.821 | R9: 5157.255 | S9: 6547.3383
A10: 6 | B10: 5200.822 | C10: 7360.801 | D10: 8493.033 | E10: 6444.164 | F10: 7408.098 | G10: 4381.682 | H10: 6966.565 | I10: 7377.334 | J10: 5111.226 | K10: 5693.893 | L10: 7231.335 | M10: 5157.894 | N10: 7803.665 | O10: 5919.264 | P10: 6527.504 | Q10: 6375.294 | R10: 4157.178 | S10: 6329.9854
A11: 7 | B11: 4465.018 | C11: 6222.005 | D11: 6108.066 | E11: 4966.204 | F11: 5512.014 | G11: 4260.822 | H11: 5001.709 | I11: 6406.012 | J11: 6232.79 | K11: 4092.741 | L11: 5356.707 | M11: 3939.341 | N11: 5465.742 | O11: 4553.264 | P11: 4741.867 | Q11: 5773.367 | R11: 3588.929 | S11: 5099.2116
A12: 8 | B12: 4042.571 | C12: 5118.486 | D12: 4329.084 | E12: 3912.005 | F12: 4402.695 | G12: 3911.157 | H12: 3616.866 | I12: 4547.102 | J12: 5334.119 | K12: 3458.606 | L12: 3918.211 | M12: 3531.814 | N12: 4064.845 | O12: 3881.36 | P12: 3795.92 | Q12: 4522.329 | R12: 2778.709 | S12: 4068.5811
A13: 9 | B13: 4391.014 | C13: 4020.884 | D13: 4879.293 | E13: 2994.867 | F13: 3608.219 | G13: 3238.139 | H13: 3663.794 | I13: 4108.625 | J13: 3786.237 | K13: 3442.721 | L13: 3403.33 | M13: 3098.526 | N13: 3175.102 | O13: 2693.82 | P13: 3466.232 | Q13: 3538.607 | R13: 2541.154 | S13: 3532.3861
A14: 10 | B14: 5097.109 | C14: 3951.926 | D14: 3806.379 | E14: 3081.905 | F14: 4048.88 | G14: 3280.981 | H14: 4484.318 | I14: 4825.201 | J14: 3783.423 | K14: 3893.284 | L14: 3081.484 | M14: 2732.815 | N14: 3074.426 | O14: 3922.912 | P14: 5275.964 | Q14: 3162.122 | R14: 3152.902 | S14: 3803.2959
A15: 11 | B15: 4243.055 | C15: 3377.328 | D15: 5125.82 | E15: 3794.323 | F15: 5519.942 | G15: 3958.532 | H15: 4831.324 | I15: 6321.496 | J15: 4897.271 | K15: 3557.628 | L15: 4228.766 | M15: 3930.395 | N15: 4123.806 | O15: 6644.621 | P15: 4622.319 | Q15: 4141.716 | R15: 3949.045 | S15: 4545.1404
A16: 12 | B16: 5251.799 | C16: 4679.286 | D16: 5663.639 | E16: 5323.072 | F16: 7063.89 | G16: 5747.037 | H16: 6482.457 | I16: 5711.181 | J16: 5745.297 | K16: 3688.393 | L16: 4597.338 | M16: 5344.461 | N16: 5311.143 | O16: 8052.219 | P16: 5860.812 | Q16: 5461.218 | R16: 5234.522 | S16: 5601.0449
A17: Total général | B17: 5203.3818 | C17: 5370.2283 | D17: 5768.4436 | E17: 5228.4942 | F17: 5713.2243 | G17: 4257.0578 | H17: 5370.9076 | I17: 6279.7889 | J17: 5687.3103 | K17: 4944.8169 | L17: 5363.2446 | M17: 4492.6421 | N17: 5861.2489 | O17: 5137.0943 | P17: 5565.5719 | Q17: 5351.8443 | R17: 4257.491 | S17: 5285.4583
A19: Moyenne de Éolien | B19: Étiquettes de colonnes
A20: Étiquettes de lignes | B20: 2006 | C20: 2007 | D20: 2008 | E20: 2009 | F20: 2010 | G20: 2011 | H20: 2012 | I20: 2013 | J20: 2014 | K20: 2015 | L20: 2016 | M20: 2017 | N20: 2018 | O20: 2019 | P20: 2020 | Q20: 2021 | R20: 2022 | S20: Total général
A21: 1 | B21: 129.023 | C21: 427.077 | D21: 614.111 | E21: 649.117 | F21: 668.12 | G21: 1229.221 | H21: 1520.984 | I21: 1263.813 | J21: 2100.334 | K21: 2176.443 | L21: 2716.194 | M21: 1909.142 | N21: 3976.68 | O21: 2968.868 | P21: 4174.923 | Q21: 3960.974 | R21: 3144.953 | S21: 1978.2339
A22: 2 | B22: 137.025 | C22: 361.065 | D22: 428.077 | E22: 494.089 | F22: 949.171 | G22: 871.157 | H22: 1083.764 | I22: 1389.151 | J22: 2357.192 | K22: 1808.531 | L22: 2748.613 | M22: 2422.158 | N22: 2732.924 | O22: 2627.507 | P22: 5907.95 | Q22: 4253.715 | R22: 5265.783 | S22: 2108.1101
A23: 3 | B23: 196.035 | C23: 363.065 | D23: 697.125 | E23: 741.133 | F23: 1149.207 | G23: 1094.197 | H23: 938.771 | I23: 1294.34 | J23: 1239.57 | K23: 1908.979 | L23: 2334.085 | M23: 2514.855 | N23: 3093.609 | O23: 4506.809 | P23: 4498.825 | Q23: 3714.417 | R23: 3461.02 | S23: 1985.0613
A24: 4 | B24: 145.026 | C24: 186.033 | D24: 416.075 | E24: 464.084 | F24: 707.127 | G24: 668.12 | H24: 1502.911 | I24: 1430.078 | J24: 1006.282 | K24: 1378.05 | L24: 1603.637 | M24: 1378.93 | N24: 2160.382 | O24: 2358.331 | P24: 2282.031 | Q24: 2949.235 | R24: 3560.29 | S24: 1423.3307
A25: 5 | B25: 166.03 | C25: 361.065 | D25: 282.051 | E25: 539.097 | F25: 725.131 | G25: 727.131 | H25: 933.063 | I25: 1112.632 | J25: 1461.836 | K25: 1519.049 | L25: 1480.649 | M25: 1400.762 | N25: 1605.95 | O25: 2266.776 | P25: 2662.786 | Q25: 3964.355 | R25: 2076.276 | S25: 1369.6846
A26: 6 | B26: 99.018 | C26: 241.043 | D26: 283.051 | E26: 405.073 | F26: 566.102 | G26: 853.154 | H26: 951.328 | I26: 1112.418 | J26: 902.475 | K26: 1199.77 | L26: 1025.024 | M26: 1396.048 | N26: 1373.513 | O26: 1907.332 | P26: 2051.309 | Q26: 1359.505 | R26: 1849.939 | S26: 1033.8884
A27: 7 | B27: 94.017 | C27: 338.061 | D27: 347.062 | E27: 538.097 | F27: 479.086 | G27: 809.146 | H27: 875.262 | I27: 829.662 | J27: 910.978 | K27: 1338.682 | L27: 974.329 | M27: 1619.103 | N27: 1085.735 | O27: 1758.16 | P27: 2105.002 | Q27: 2315.103 | R27: 1885.33 | S27: 1076.6362
A28: 8 | B28: 191.034 | C28: 285.051 | D28: 407.073 | E28: 355.064 | F28: 668.12 | G28: 664.12 | H28: 861.719 | I28: 705.577 | J28: 933.67 | K28: 1076.516 | L28: 1134.446 | M28: 1170.41 | N28: 1402.538 | O28: 1662.521 | P28: 2047.002 | Q28: 2225.564 | R28: 2077.602 | S28: 1051.0604
A29: 9 | B29: 152.027 | C29: 277.05 | D29: 464.084 | E29: 542.098 | F29: 548.099 | G29: 821.148 | H29: 883.669 | I29: 899.816 | J29: 678.464 | K29: 1585.603 | L29: 953.063 | M29: 1557.968 | N29: 1585.212 | O29: 2696.32 | P29: 2145.086 | Q29: 1657.392 | R29: 2293.837 | S29: 1161.2315
A30: 10 | B30: 237.043 | C30: 283.051 | D30: 475.086 | E30: 632.114 | F30: 1034.186 | G30: 1035.186 | H30: 1308.577 | I30: 1543.666 | J30: 1209.845 | K30: 1218.133 | L30: 1340.852 | M30: 1972.717 | N30: 2449.602 | O30: 3429.099 | P30: 4320.308 | Q30: 3489.485 | R30: 3432.376 | S30: 1730.078
A31: 11 | B31: 299.054 | C31: 434.078 | D31: 637.115 | E31: 1296.233 | F31: 969.174 | G31: 909.164 | H31: 1249.205 | I31: 1714.499 | J31: 1411.79 | K31: 2433.612 | L31: 2188.501 | M31: 2172.685 | N31: 2796.145 | O31: 3416.78 | P31: 3154.791 | Q31: 2710.387 | R31: 4626.758 | S31: 1907.0571
A32: 12 | B32: 324.058 | C32: 584.105 | D32: 660.119 | E32: 940.169 | F32: 950.171 | G32: 1944.35 | H32: 2193.274 | I32: 1916.751 | J32: 1958.883 | K32: 2527.055 | L32: 1388.663 | M32: 3084.339 | N32: 3613.452 | O32: 4715.008 | P32: 4383.911 | Q32: 4331.128 | R32: 4364.634 | S32: 2345.8865
A33: Total général | B33: 180.7825 | C33: 345.062 | D33: 475.91908 | E33: 633.03067 | F33: 784.4745 | G33: 968.84117 | H33: 1191.8772 | I33: 1267.7002 | J33: 1347.6099 | K33: 1680.8686 | L33: 1657.338 | M33: 1883.2598 | N33: 2322.9785 | O33: 2859.4592 | P33: 3311.1603 | Q33: 3077.605 | R33: 3169.8998 | S33: 1597.5216
A35: Moyenne de Nucléaire | B35: Étiquettes de colonnes
A36: Étiquettes de lignes | B36: 2006 | C36: 2007 | D36: 2008 | E36: 2009 | F36: 2010 | G36: 2011 | H36: 2012 | I36: 2013 | J36: 2014 | K36: 2015 | L36: 2016 | M36: 2017 | N36: 2018 | O36: 2019 | P36: 2020 | Q36: 2021 | R36: 2022 | S36: Total général
A37: 1 | B37: 135581.95 | C37: 129735.44 | D37: 129923.35 | E37: 136557.88 | F37: 128292.76 | G37: 138909.82 | H37: 135687.63 | I37: 134319.11 | J37: 135384.94 | K37: 138614.25 | L37: 131863.55 | M37: 128272.38 | N37: 129237.36 | O37: 127358.57 | P37: 118755.94 | Q37: 118085.18 | R37: 111862.4 | S37: 129908.38
A38: 2 | B38: 111416.99 | C38: 114708.5 | D38: 123370.66 | E38: 117351.4 | F38: 115196.48 | G38: 121352.74 | H38: 122565.79 | I38: 116396.59 | J38: 115457.12 | K38: 118645.63 | L38: 118312.26 | M38: 107040.27 | N38: 115269.05 | O38: 114250.76 | P38: 105638.33 | Q38: 96487.993 | R38: 94127.124 | S38: 113387.51
A39: 3 | B39: 112414.14 | C39: 116790.69 | D39: 118281.87 | E39: 114347.82 | F39: 114382.67 | G39: 119591.67 | H39: 119245.98 | I39: 116706.88 | J39: 113702.25 | K39: 117108.44 | L39: 117876.3 | M39: 108798.42 | N39: 113291.11 | O39: 112901.59 | P39: 97714.37 | Q39: 100674.87 | R39: 85750.867 | S39: 111740
A40: 4 | B40: 114187.19 | C40: 101333.37 | D40: 109092.34 | E40: 98544.985 | F40: 99668.426 | G40: 104735.57 | H40: 105259.43 | I40: 100186.1 | J40: 99323.913 | K40: 99393.986 | L40: 98619.128 | M40: 101043 | N40: 97451.631 | O40: 101109.58 | P40: 85870.559 | Q40: 86700.855 | R40: 69785.579 | S40: 98370.92
A41: 5 | B41: 108225.51 | C41: 101563.71 | D41: 102006.21 | E41: 95638.402 | F41: 93362.235 | G41: 105566.54 | H41: 92837.989 | I41: 99269.63 | J41: 99269.357 | K41: 96932.331 | L41: 94016.725 | M41: 95666.749 | N41: 97495.218 | O41: 100989.6 | P41: 79563.073 | Q41: 87953.999 | R41: 65809.978 | S41: 95068.663
A42: 6 | B42: 104758.22 | C42: 98523.769 | D42: 91410.369 | E42: 86803.48 | F42: 94335.046 | G42: 103918.03 | H42: 84994.337 | I42: 91415.825 | J42: 98890.501 | K42: 97938.391 | L42: 91412.76 | M42: 86043.753 | N42: 91391.126 | O42: 91228.342 | P42: 68777.753 | Q42: 88324.864 | R42: 64482.038 | S42: 90273.447
A43: 7 | B43: 105161.32 | C43: 101666.76 | D43: 101837.05 | E43: 92456.012 | F43: 101295.79 | G43: 106785.19 | H43: 92115.647 | I43: 98138.306 | J43: 106619.16 | K43: 106076.1 | L43: 90469.67 | M43: 90039.041 | N43: 95721.776 | O43: 93226.276 | P43: 72325.808 | Q43: 91149.167 | R43: 60385.593 | S43: 94439.334
A44: 8 | B44: 104570.31 | C44: 104203.58 | D44: 102460.84 | E44: 90316.491 | F44: 103451.93 | G44: 100293.78 | H44: 90827.355 | I44: 95377.112 | J44: 99057.198 | K44: 102283.51 | L44: 86803.211 | M44: 91336.844 | N44: 87546.408 | O44: 88794.004 | P44: 73715.969 | Q44: 93107.481 | R44: 58554.054 | S44: 92511.769
...

Sheet Graphiques
A20: Étiquettes de lignes | B20: Somme de Hydraulique | C20: Somme de Éolien | D20: Somme de Solaire | E20: Somme de Nucléaire_Elec
A21: 2006 | B21: 62440.582 | C21: 2169.39 | D21: 0 | E21: 454801.95
A22: 2007 | B22: 64442.74 | C22: 4140.744 | D22: 0 | E22: 444352.59
A23: 2008 | B23: 69221.323 | C23: 5711.029 | D23: 0 | E23: 444000.19
A24: 2009 | B24: 62741.931 | C24: 7596.368 | D24: 0 | E24: 414348.8
A25: 2010 | B25: 68558.692 | C25: 9413.694 | D25: 0 | E25: 432722.74
A26: 2011 | B26: 51084.694 | C26: 11626.094 | D26: 1936.539 | E26: 446627.84
A27: 2012 | B27: 64450.891 | C27: 14302.527 | D27: 3687.078 | E27: 429777.32
A28: 2013 | B28: 75357.467 | C28: 15212.403 | D28: 4336.856 | E28: 428041.16
A29: 2014 | B29: 68247.724 | C29: 16171.319 | D29: 5487.194 | E29: 440365.82
A30: 2015 | B30: 59337.803 | C30: 20170.423 | D30: 6739.303 | E30: 441926.13
A31: 2016 | B31: 64358.935 | C31: 19888.056 | D31: 7665.799 | E31: 407355.53
A32: 2017 | B32: 53911.705 | C32: 22599.117 | D32: 8607.83 | E32: 402452.05
... A37: 2022 | B37: 51089.892 | C37: 38038.798 | D37: 19001.106 | E37: 297761.64
A38: Total général | B38: 1078233.5 | C38: 325894.4 | D38: 108461.98 | E38: 7045589.5
A40: Source | B40: Moyenne (GWh)
A41: Nucléaire | B41: =AVERAGE(Production!E:E)/3 -> 34537.203
A42: Hydraulique | B42: =AVERAGE(Production!B:B) -> 5285.4583
A43: Éolien | B43: =MEDIAN(Production!C:C) -> 1302.405
A44: Solaire | B44: =AVERAGE(Production!D:D) -> 753.20819
